Workbook

Sheet Calcul puissance cinétique
A1: Longitude | B1: Lattitude | C1: Vitesse moyenne zone morte (m/s) | D1: Vitesse moyenne eaux vives (m/s) | E1: Vc (m/s) | F1: Puissance cinétique (w)
A2: -4.82438 | B2: 48.3393 | C2: 0.86575941 | D2: 1.700307 | E2: =C2+(($O$3-45)/50*(D2-C2)) -> 1.6168522 | F2: =(1/2)*$P$3*$R$3*(E2^3) -> 170049.17 | O2: Coefficient de marée | P2: Densité de l'eau salée | Q2: Rayon du rotor | R2: Surface du rotor
A3: -5.06489 | B3: 48.4299 | C3: 0.71459964 | D3: 1.6349446 | E3: =C3+(($O$3-45)/50*(D3-C3)) -> 1.5429101 | F3: =(1/2)*$P$3*$R$3*(E3^3) -> 147769.69 | O3: 90 | P3: 1025 | Q3: 5 | R3: =(Q3^2)*3.14 -> 78.5
A4: -5.07833 | B4: 48.4138 | C4: 0.93578361 | D4: 1.4210895 | E4: =C4+(($O$3-45)/50*(D4-C4)) -> 1.3725589 | F4: =(1/2)*$P$3*$R$3*(E4^3) -> 104029.49
A5: -4.79251 | B5: 48.3415 | C5: 0.51830667 | D5: 1.4565389 | E5: =C5+(($O$3-45)/50*(D5-C5)) -> 1.3627157 | F5: =(1/2)*$P$3*$R$3*(E5^3) -> 101807.4
A6: -5.06707 | B6: 48.4837 | C6: 0.59213675 | D6: 1.3897502 | E6: =C6+(($O$3-45)/50*(D6-C6)) -> 1.3099889 | F6: =(1/2)*$P$3*$R$3*(E6^3) -> 90441.21
A7: -4.96762 | B7: 48.3872 | C7: 0.65383544 | D7: 1.3575911 | E7: =C7+(($O$3-45)/50*(D7-C7)) -> 1.2872155 | F7: =(1/2)*$P$3*$R$3*(E7^3) -> 85805.941
A8: -4.99953 | B8: 48.3948 | C8: 0.677636 | D8: 1.2714719 | E8: =C8+(($O$3-45)/50*(D8-C8)) -> 1.2120883 | F8: =(1/2)*$P$3*$R$3*(E8^3) -> 71641.766 | J8: Voici la feuille calcul de puissance cinétique, les données du tableur à gauche proviennent du SHOM lors de la réalisation de l'étude des courants dans le passage du fromveur. La feuille permet en insérant dans les cases oranges un coefficient de marée et un rayon du rotor. De déterminé la vitesse Vc (vitesse moyenne cinétique) et la puissance cinétique exploitable.
A9: -5.0201 | B9: 48.4596 | C9: 0.73487736 | D9: 1.2544129 | E9: =C9+(($O$3-45)/50*(D9-C9)) -> 1.2024594 | F9: =(1/2)*$P$3*$R$3*(E9^3) -> 69947.916
A10: -4.83597 | B10: 48.3663 | C10: 0.70587762 | D10: 1.2400997 | E10: =C10+(($O$3-45)/50*(D10-C10)) -> 1.1866775 | F10: =(1/2)*$P$3*$R$3*(E10^3) -> 67229.773
A11: -4.82043 | B11: 48.3653 | C11: 0.7313062 | D11: 1.2371655 | E11: =C11+(($O$3-45)/50*(D11-C11)) -> 1.1865795 | F11: =(1/2)*$P$3*$R$3*(E11^3) -> 67213.124
A12: -4.91657 | B12: 48.3614 | C12: 0.47265453 | D12: 1.2567415 | E12: =C12+(($O$3-45)/50*(D12-C12)) -> 1.1783328 | F12: =(1/2)*$P$3*$R$3*(E12^3) -> 65821.454
A13: -4.89551 | B13: 48.3917 | C13: 0.33356404 | D13: 1.2535143 | E13: =C13+(($O$3-45)/50*(D13-C13)) -> 1.1615193 | F13: =(1/2)*$P$3*$R$3*(E13^3) -> 63043.857
A14: -4.79434 | B14: 48.3621 | C14: 0.61723023 | D14: 1.2180532 | E14: =C14+(($O$3-45)/50*(D14-C14)) -> 1.1579709 | F14: =(1/2)*$P$3*$R$3*(E14^3) -> 62467.831
A15: -4.89823 | B15: 48.3203 | C15: 0.5011656 | D15: 1.2242538 | E15: =C15+(($O$3-45)/50*(D15-C15)) -> 1.151945 | F15: =(1/2)*$P$3*$R$3*(E15^3) -> 61497.68
A16: -5.12457 | B16: 48.4777 | C16: 0.39952708 | D16: 1.2155894 | E16: =C16+(($O$3-45)/50*(D16-C16)) -> 1.1339832 | F16: =(1/2)*$P$3*$R$3*(E16^3) -> 58665.575
A17: -4.91698 | B17: 48.3636 | C17: 0.62977673 | D17: 1.168815 | E17: =C17+(($O$3-45)/50*(D17-C17)) -> 1.1149112 | F17: =(1/2)*$P$3*$R$3*(E17^3) -> 55755.068
A18: -4.82021 | B18: 48.3795 | C18: 0.68396628 | D18: 1.1616883 | E18: =C18+(($O$3-45)/50*(D18-C18)) -> 1.1139161 | F18: =(1/2)*$P$3*$R$3*(E18^3) -> 55605.905
A19: -4.83535 | B19: 48.3775 | C19: 0.67099765 | D19: 1.1274117 | E19: =C19+(($O$3-45)/50*(D19-C19)) -> 1.0817703 | F19: =(1/2)*$P$3*$R$3*(E19^3) -> 50929.418
A20: -4.97218 | B20: 48.3562 | C20: 0.73527664 | D20: 1.1166474 | E20: =C20+(($O$3-45)/50*(D20-C20)) -> 1.0785103 | F20: =(1/2)*$P$3*$R$3*(E20^3) -> 50470.365
... A22: -4.983 | B22: 48.4353 | C22: 0.55756058 | D22: 1.120892 | E22: =C22+(($O$3-45)/50*(D22-C22)) -> 1.0645589 | F22: =(1/2)*$P$3*$R$3*(E22^3) -> 48536.959
A23: -4.78965 | B23: 48.335 | C23: 0.51229817 | D23: 1.1114839 | E23: =C23+(($O$3-45)/50*(D23-C23)) -> 1.0515654 | F23: =(1/2)*$P$3*$R$3*(E23^3) -> 46781.307 | J23: Légende
A24: -4.90355 | B24: 48.3672 | C24: 0.58200063 | D24: 1.1031138 | E24: =C24+(($O$3-45)/50*(D24-C24)) -> 1.0510025 | F24: =(1/2)*$P$3*$R$3*(E24^3) -> 46706.225
A25: -4.9937 | B25: 48.5062 | C25: 0.46597047 | D25: 1.0894462 | E25: =C25+(($O$3-45)/50*(D25-C25)) -> 1.0270986 | F25: =(1/2)*$P$3*$R$3*(E25^3) -> 43591.315 | N25: Case de calcul
A26: -4.78715 | B26: 48.3414 | C26: 0.35954969 | D26: 1.0850102 | E26: =C26+(($O$3-45)/50*(D26-C26)) -> 1.0124641 | F26: =(1/2)*$P$3*$R$3*(E26^3) -> 41754.419
A27: -4.82478 | B27: 48.371 | C27: 0.34065295 | D27: 1.0808247 | E27: =C27+(($O$3-45)/50*(D27-C27)) -> 1.0068075 | F27: =(1/2)*$P$3*$R$3*(E27^3) -> 41058.478 | N27: Case de donnée
A28: -4.80595 | B28: 48.386 | C28: 0.56992167 | D28: 1.0542987 | E28: =C28+(($O$3-45)/50*(D28-C28)) -> 1.005861 | F28: =(1/2)*$P$3*$R$3*(E28^3) -> 40942.791
A29: -4.84944 | B29: 48.5304 | C29: 0.51239658 | D29: 1.0466811 | E29: =C29+(($O$3-45)/50*(D29-C29)) -> 0.99325263 | F29: =(1/2)*$P$3*$R$3*(E29^3) -> 39422.367
A30: -5.08925 | B30: 48.3321 | C30: 0.46839773 | D30: 1.0507542 | E30: =C30+(($O$3-45)/50*(D30-C30)) -> 0.99251856 | F30: =(1/2)*$P$3*$R$3*(E30^3) -> 39335.025
A31: -4.88195 | B31: 48.3722 | C31: 0.51744025 | D31: 1.0400117 | E31: =C31+(($O$3-45)/50*(D31-C31)) -> 0.98775455 | F31: =(1/2)*$P$3*$R$3*(E31^3) -> 38771.325
A32: -4.8435 | B32: 48.3866 | C32: 0.54714851 | D32: 1.0330438 | E32: =C32+(($O$3-45)/50*(D32-C32)) -> 0.9844543 | F32: =(1/2)*$P$3*$R$3*(E32^3) -> 38383.998
A33: -4.88319 | B33: 48.3099 | C33: 0.76375916 | D33: 1.0057552 | E33: =C33+(($O$3-45)/50*(D33-C33)) -> 0.98155559 | F33: =(1/2)*$P$3*$R$3*(E33^3) -> 38045.932
A34: -4.79998 | B34: 48.3299 | C34: 0.47506909 | D34: 1.0352116 | E34: =C34+(($O$3-45)/50*(D34-C34)) -> 0.97919731 | F34: =(1/2)*$P$3*$R$3*(E34^3) -> 37772.363
A35: -4.88194 | B35: 48.5074 | C35: 0.39160769 | D35: 1.0432056 | E35: =C35+(($O$3-45)/50*(D35-C35)) -> 0.97804585 | F35: =(1/2)*$P$3*$R$3*(E35^3) -> 37639.268
A36: -4.83858 | B36: 48.3573 | C36: 0.43726435 | D36: 1.0374351 | E36: =C36+(($O$3-45)/50*(D36-C36)) -> 0.97741807 | F36: =(1/2)*$P$3*$R$3*(E36^3) -> 37566.835
A37: -4.78025 | B37: 48.3132 | C37: 0.51868339 | D37: 1.0224261 | E37: =C37+(($O$3-45)/50*(D37-C37)) -> 0.97205182 | F37: =(1/2)*$P$3*$R$3*(E37^3) -> 36951.475
A38: -5.04589 | B38: 48.4366 | C38: 0.40720531 | D38: 1.0335108 | E38: =C38+(($O$3-45)/50*(D38-C38)) -> 0.97088028 | F38: =(1/2)*$P$3*$R$3*(E38^3) -> 36818.032
A39: -4.85763 | B39: 48.3817 | C39: 0.33251649 | D39: 1.0354895 | E39: =C39+(($O$3-45)/50*(D39-C39)) -> 0.96519216 | F39: =(1/2)*$P$3*$R$3*(E39^3) -> 36174.695
... A16943: -4.96797 | B16943: 48.5106 | C16943: 0.13026713 | D16943: 0.20399275 | E16943: =C16943+(($O$3-45)/50*(D16943-C16943)) -> 0.19662019 | F16943: =(1/2)*$P$3*$R$3*(E16943^3) -> 305.8073
A16944: -4.8897 | B16944: 48.4025 | C16944: 0.44078859 | E16944: =C16944+(($O$3-45)/50*(D16944-C16944)) -> 0.044078859
...

Sheet Coefficient de marée
B1: 2025
B2: Janvier | F2: Février | J2: Mars | N2: Avril | R2: Mai | V2: Juin | Z2: Juillet | AD2: Août | AH2: Septembre | AL2: Octobre | AP2: Novembre | AT2: Décembre
B3: Jour | C3: Coef bas | D3: Coef haut | E3: Coef moy | F3: Jour | G3: Coef bas | H3: Coef haut | I3: Coef moy | J3: Jour | K3: Coef bas | L3: Coef haut | M3: Coef moy | N3: Jour | O3: Coef bas | P3: Coef haut | Q3: Coef moy | R3: Jour | S3: Coef bas | T3: Coef haut | U3: Coef moy | V3: Jour | W3: Coef bas | X3: Coef haut | Y3: Coef moy | Z3: Jour | AA3: Coef bas | AB3: Coef haut | AC3: Coef moy | AD3: Jour | AE3: Coef bas | AF3: Coef haut | AG3: Coef moy | AH3: Jour | AI3: Coef bas | AJ3: Coef haut | AK3: Coef moy | AL3: Jour | AM3: Coef bas | AN3: Coef haut | AO3: Coef moy | AP3: Jour | AQ3: Coef bas | AR3: Coef haut | AS3: Coef moy | AT3: Jour | AU3: Coef bas | AV3: Coef haut | AW3: Coef moy | AY3: Mois | AZ3: Coef moy/mois
B4: 1 | C4: 80 | D4: 81 | E4: =AVERAGE(C4,D4) -> 80.5 | F4: 1 | G4: 99 | H4: 98 | I4: =AVERAGE(G4,H4) -> 98.5 | J4: 1 | K4: 108 | L4: 110 | M4: =AVERAGE(K4,L4) -> 109 | N4: 1 | O4: 107 | P4: 102 | Q4: =AVERAGE(O4,P4) -> 104.5 | R4: 1 | S4: 89 | T4: 82 | U4: =AVERAGE(S4,T4) -> 85.5 | V4: 1 | W4: 63 | X4: 58 | Y4: =AVERAGE(W4,X4) -> 60.5 | Z4: 1 | AA4: 62 | AB4: 57 | AC4: =AVERAGE(AA4,AB4) -> 59.5 | AD4: 1 | AE4: 47 | AF4: 42 | AG4: =AVERAGE(AE4,AF4) -> 44.5 | AH4: 1 | AI4: 27 | AK4: =AVERAGE(AI4,AJ4) -> 27 | AL4: 1 | AM4: 24 | AO4: =AVERAGE(AM4,AN4) -> 24 | AP4: 1 | AQ4: 44 | AR4: 52 | AS4: =AVERAGE(AQ4,AR4) -> 48 | AT4: 1 | AU4: 58 | AV4: 64 | AW4: =AVERAGE(AU4,AV4) -> 61 | AY4: Janv | AZ4: =AVERAGE(E4:E34) -> 66.387097 | BC4: Cette page a pour but de définir les coefficients de marée applicable. Elle permettront par la suite de connaitre la puissance qui serait produite par une hydrolienne dans un cas optimiste sans power curve. Ces données dâtent de 2025 et sont trouvable sur le site : https://maree.info/82/coefficients?c=gm Cette page calcul également les coefficients moyenne par mois.
B5: 2 | C5: 82 | D5: 83 | E5: =AVERAGE(C5,D5) -> 82.5 | F5: 2 | G5: 96 | H5: 93 | I5: =AVERAGE(G5,H5) -> 94.5 | J5: 2 | K5: 111 | L5: 109 | M5: =AVERAGE(K5,L5) -> 110 | N5: 2 | O5: 95 | P5: 87 | Q5: =AVERAGE(O5,P5) -> 91 | R5: 2 | S5: 74 | T5: 66 | U5: =AVERAGE(S5,T5) -> 70 | V5: 2 | W5: 53 | X5: 49 | Y5: =AVERAGE(W5,X5) -> 51 | Z5: 2 | AA5: 53 | AB5: 49 | AC5: =AVERAGE(AA5,AB5) -> 51 | AD5: 2 | AE5: 37 | AF5: 33 | AG5: =AVERAGE(AE5,AF5) -> 35 | AH5: 2 | AI5: 24 | AJ5: 24 | AK5: =AVERAGE(AI5,AJ5) -> 24 | AL5: 2 | AM5: 28 | AN5: 34 | AO5: =AVERAGE(AM5,AN5) -> 31 | AP5: 2 | AQ5: 60 | AR5: 68 | AS5: =AVERAGE(AQ5,AR5) -> 64 | AT5: 2 | AU5: 70 | AV5: 76 | AW5: =AVERAGE(AU5,AV5) -> 73 | AY5: Fevr | AZ5: =AVERAGE(I4:I31) -> 66.071429
B6: 3 | C6: 82 | D6: 81 | E6: =AVERAGE(C6,D6) -> 81.5 | F6: 3 | G6: 89 | H6: 84 | I6: =AVERAGE(G6,H6) -> 86.5 | J6: 3 | K6: 107 | L6: 102 | M6: =AVERAGE(K6,L6) -> 104.5 | N6: 3 | O6: 77 | P6: 68 | Q6: =AVERAGE(O6,P6) -> 72.5 | R6: 3 | S6: 58 | T6: 51 | U6: =AVERAGE(S6,T6) -> 54.5 | V6: 3 | W6: 46 | Y6: =AVERAGE(W6,X6) -> 46 | Z6: 3 | AA6: 45 | AC6: =AVERAGE(AA6,AB6) -> 45 | AD6: 3 | AE6: 30 | AG6: =AVERAGE(AE6,AF6) -> 30 | AH6: 3 | AI6: 28 | AJ6: 34 | AK6: =AVERAGE(AI6,AJ6) -> 31 | AL6: 3 | AM6: 42 | AN6: 50 | AO6: =AVERAGE(AM6,AN6) -> 46 | AP6: 3 | AQ6: 76 | AR6: 84 | AS6: =AVERAGE(AQ6,AR6) -> 80 | AT6: 3 | AU6: 82 | AV6: 87 | AW6: =AVERAGE(AU6,AV6) -> 84.5 | AY6: Mars | AZ6: =AVERAGE(M4:M34) -> 71.774194
B7: 4 | C7: 80 | D7: 78 | E7: =AVERAGE(C7,D7) -> 79 | F7: 4 | G7: 78 | H7: 71 | I7: =AVERAGE(G7,H7) -> 74.5 | J7: 4 | K7: 96 | L7: 89 | M7: =AVERAGE(K7,L7) -> 92.5 | N7: 4 | O7: 58 | P7: 50 | Q7: =AVERAGE(O7,P7) -> 54 | R7: 4 | S7: 45 | T7: 42 | U7: =AVERAGE(S7,T7) -> 43.5 | V7: 4 | W7: 44 | X7: 43 | Y7: =AVERAGE(W7,X7) -> 43.5 | Z7: 4 | AA7: 42 | AB7: 39 | AC7: =AVERAGE(AA7,AB7) -> 40.5 | AD7: 4 | AE7: 29 | AF7: 31 | AG7: =AVERAGE(AE7,AF7) -> 30 | AH7: 4 | AI7: 41 | AJ7: 49 | AK7: =AVERAGE(AI7,AJ7) -> 45 | AL7: 4 | AM7: 59 | AN7: 68 | AO7: =AVERAGE(AM7,AN7) -> 63.5 | AP7: 4 | AQ7: 90 | AR7: 96 | AS7: =AVERAGE(AQ7,AR7) -> 93 | AT7: 4 | AU7: 91 | AV7: 94 | AW7: =AVERAGE(AU7,AV7) -> 92.5 | AY7: Avril | AZ7: =AVERAGE(Q4:Q33) -> 69.116667
B8: 5 | C8: 75 | D8: 72 | E8: =AVERAGE(C8,D8) -> 73.5 | F8: 5 | G8: 64 | H8: 57 | I8: =AVERAGE(G8,H8) -> 60.5 | J8: 5 | K8: 80 | L8: 72 | M8: =AVERAGE(K8,L8) -> 76 | N8: 5 | O8: 42 | P8: 37 | Q8: =AVERAGE(O8,P8) -> 39.5 | R8: 5 | S8: 40 | U8: =AVERAGE(S8,T8) -> 40 | V8: 5 | W8: 43 | X8: 44 | Y8: =AVERAGE(W8,X8) -> 43.5 | Z8: 5 | AA8: 38 | AB8: 38 | AC8: =AVERAGE(AA8,AB8) -> 38 | AD8: 5 | AE8: 34 | AF8: 38 | AG8: =AVERAGE(AE8,AF8) -> 36 | AH8: 5 | AI8: 56 | AJ8: 65 | AK8: =AVERAGE(AI8,AJ8) -> 60.5 | AL8: 5 | AM8: 76 | AN8: 84 | AO8: =AVERAGE(AM8,AN8) -> 80 | AP8: 5 | AQ8: 101 | AR8: 104 | AS8: =AVERAGE(AQ8,AR8) -> 102.5 | AT8: 5 | AU8: 97 | AV8: 98 | AW8: =AVERAGE(AU8,AV8) -> 97.5 | AY8: Mai | AZ8: =AVERAGE(U4:U34) -> 66.467742
B9: 6 | C9: 68 | D9: 64 | E9: =AVERAGE(C9,D9) -> 66 | F9: 6 | G9: 50 | H9: 46 | I9: =AVERAGE(G9,H9) -> 48 | J9: 6 | K9: 62 | L9: 53 | M9: =AVERAGE(K9,L9) -> 57.5 | N9: 6 | O9: 35 | Q9: =AVERAGE(O9,P9) -> 35 | R9: 6 | S9: 40 | T9: 43 | U9: =AVERAGE(S9,T9) -> 41.5 | V9: 6 | W9: 46 | X9: 48 | Y9: =AVERAGE(W9,X9) -> 47 | Z9: 6 | AA9: 39 | AB9: 41 | AC9: =AVERAGE(AA9,AB9) -> 40 | AD9: 6 | AE9: 43 | AF9: 49 | AG9: =AVERAGE(AE9,AF9) -> 46 | AH9: 6 | AI9: 72 | AJ9: 80 | AK9: =AVERAGE(AI9,AJ9) -> 76 | AL9: 6 | AM9: 91 | AN9: 98 | AO9: =AVERAGE(AM9,AN9) -> 94.5 | AP9: 6 | AQ9: 106 | AR9: 106 | AS9: =AVERAGE(AQ9,AR9) -> 106 | AT9: 6 | AU9: 98 | AV9: 97 | AW9: =AVERAGE(AU9,AV9) -> 97.5 | AY9: Juin | AZ9: =AVERAGE(Y4:Y33) -> 64.65
B10: 7 | C10: 61 | D10: 58 | E10: =AVERAGE(C10,D10) -> 59.5 | F10: 7 | G10: 43 | I10: =AVERAGE(G10,H10) -> 43 | J10: 7 | K10: 45 | L10: 39 | M10: =AVERAGE(K10,L10) -> 42 | N10: 7 | O10: 37 | P10: 42 | Q10: =AVERAGE(O10,P10) -> 39.5 | R10: 7 | S10: 46 | T10: 50 | U10: =AVERAGE(S10,T10) -> 48 | V10: 7 | W10: 51 | X10: 53 | Y10: =AVERAGE(W10,X10) -> 52 | Z10: 7 | AA10: 44 | AB10: 47 | AC10: =AVERAGE(AA10,AB10) -> 45.5 | AD10: 7 | AE10: 55 | AF10: 61 | AG10: =AVERAGE(AE10,AF10) -> 58 | AH10: 7 | AI10: 86 | AJ10: 92 | AK10: =AVERAGE(AI10,AJ10) -> 89 | AL10: 7 | AM10: 103 | AN10: 107 | AO10: =AVERAGE(AM10,AN10) -> 105 | AP10: 7 | AQ10: 105 | AR10: 102 | AS10: =AVERAGE(AQ10,AR10) -> 103.5 | AT10: 7 | AU10: 95 | AV10: 92 | AW10: =AVERAGE(AU10,AV10) -> 93.5 | AY10: Juillet | AZ10: =AVERAGE(AC4:AC34) -> 64.774194
B11: 8 | C11: 55 | E11: =AVERAGE(C11,D11) -> 55 | F11: 8 | G11: 43 | H11: 46 | I11: =AVERAGE(G11,H11) -> 44.5 | J11: 8 | K11: 36 | M11: =AVERAGE(K11,L11) -> 36 | N11: 8 | O11: 47 | P11: 54 | Q11: =AVERAGE(O11,P11) -> 50.5 | R11: 8 | S11: 54 | T11: 58 | U11: =AVERAGE(S11,T11) -> 56 | V11: 8 | W11: 56 | X11: 59 | Y11: =AVERAGE(W11,X11) -> 57.5 | Z11: 8 | AA11: 50 | AB11: 54 | AC11: =AVERAGE(AA11,AB11) -> 52 | AD11: 8 | AE11: 67 | AF11: 73 | AG11: =AVERAGE(AE11,AF11) -> 70 | AH11: 8 | AI11: 97 | AJ11: 101 | AK11: =AVERAGE(AI11,AJ11) -> 99 | AL11: 8 | AM11: 109 | AN11: 110 | AO11: =AVERAGE(AM11,AN11) -> 109.5 | AP11: 8 | AQ11: 98 | AR11: 93 | AS11: =AVERAGE(AQ11,AR11) -> 95.5 | AT11: 8 | AU11: 88 | AV11: 83 | AW11: =AVERAGE(AU11,AV11) -> 85.5 | AY11: Août | AZ11: =AVERAGE(AG4:AG34) -> 64.790323
B12: 9 | C12: 54 | D12: 54 | E12: =AVERAGE(C12,D12) -> 54 | F12: 9 | G12: 50 | H12: 56 | I12: =AVERAGE(G12,H12) -> 53 | J12: 9 | K12: 37 | L12: 41 | M12: =AVERAGE(K12,L12) -> 39 | N12: 9 | O12: 59 | P12: 65 | Q12: =AVERAGE(O12,P12) -> 62 | R12: 9 | S12: 62 | T12: 65 | U12: =AVERAGE(S12,T12) -> 63.5 | V12: 9 | W12: 61 | X12: 64 | Y12: =AVERAGE(W12,X12) -> 62.5 | Z12: 9 | AA12: 58 | AB12: 62 | AC12: =AVERAGE(AA12,AB12) -> 60 | AD12: 9 | AE12: 78 | AF12: 83 | AG12: =AVERAGE(AE12,AF12) -> 80.5 | AH12: 9 | AI12: 104 | AJ12: 106 | AK12: =AVERAGE(AI12,AJ12) -> 105 | AL12: 9 | AM12: 109 | AN12: 106 | AO12: =AVERAGE(AM12,AN12) -> 107.5 | AP12: 9 | AQ12: 87 | AR12: 79 | AS12: =AVERAGE(AQ12,AR12) -> 83 | AT12: 9 | AU12: 78 | AV12: 72 | AW12: =AVERAGE(AU12,AV12) -> 75 | AY12: Sept | AZ12: =AVERAGE(AK4:AK33) -> 66.183333
B13: 10 | C13: 55 | D13: 58 | E13: =AVERAGE(C13,D13) -> 56.5 | F13: 10 | G13: 62 | H13: 68 | I13: =AVERAGE(G13,H13) -> 65 | J13: 10 | K13: 47 | L13: 54 | M13: =AVERAGE(K13,L13) -> 50.5 | N13: 10 | O13: 70 | P13: 74 | Q13: =AVERAGE(O13,P13) -> 72 | R13: 10 | S13: 68 | T13: 71 | U13: =AVERAGE(S13,T13) -> 69.5 | V13: 10 | W13: 66 | X13: 67 | Y13: =AVERAGE(W13,X13) -> 66.5 | Z13: 10 | AA13: 65 | AB13: 68 | AC13: =AVERAGE(AA13,AB13) -> 66.5 | AD13: 10 | AE13: 87 | AF13: 90 | AG13: =AVERAGE(AE13,AF13) -> 88.5 | AH13: 10 | AI13: 106 | AJ13: 104 | AK13: =AVERAGE(AI13,AJ13) -> 105 | AL13: 10 | AM13: 102 | AN13: 96 | AO13: =AVERAGE(AM13,AN13) -> 99 | AP13: 10 | AQ13: 72 | AR13: 65 | AS13: =AVERAGE(AQ13,AR13) -> 68.5 | AT13: 10 | AU13: 67 | AV13: 61 | AW13: =AVERAGE(AU13,AV13) -> 64 | AY13: Octobre | AZ13: =AVERAGE(AO4:AO34) -> 65.580645
B14: 11 | C14: 61 | D14: 65 | E14: =AVERAGE(C14,D14) -> 63 | F14: 11 | G14: 74 | H14: 78 | I14: =AVERAGE(G14,H14) -> 76 | J14: 11 | K14: 61 | L14: 68 | M14: =AVERAGE(K14,L14) -> 64.5 | N14: 11 | O14: 78 | P14: 81 | Q14: =AVERAGE(O14,P14) -> 79.5 | R14: 11 | S14: 73 | T14: 75 | U14: =AVERAGE(S14,T14) -> 74 | V14: 11 | W14: 69 | X14: 70 | Y14: =AVERAGE(W14,X14) -> 69.5 | Z14: 11 | AA14: 71 | AB14: 74 | AC14: =AVERAGE(AA14,AB14) -> 72.5 | AD14: 11 | AE14: 93 | AF14: 95 | AG14: =AVERAGE(AE14,AF14) -> 94 | AH14: 11 | AI14: 101 | AJ14: 96 | AK14: =AVERAGE(AI14,AJ14) -> 98.5 | AL14: 11 | AM14: 89 | AN14: 81 | AO14: =AVERAGE(AM14,AN14) -> 85 | AP14: 11 | AQ14: 58 | AR14: 52 | AS14: =AVERAGE(AQ14,AR14) -> 55 | AT14: 11 | AU14: 57 | AV14: 52 | AW14: =AVERAGE(AU14,AV14) -> 54.5 | AY14: Novembre | AZ14: =AVERAGE(AS4:AS33) -> 67.133333
B15: 12 | C15: 69 | D15: 74 | E15: =AVERAGE(C15,D15) -> 71.5 | F15: 12 | G15: 82 | H15: 86 | I15: =AVERAGE(G15,H15) -> 84 | J15: 12 | K15: 73 | L15: 78 | M15: =AVERAGE(K15,L15) -> 75.5 | N15: 12 | O15: 83 | P15: 84 | Q15: =AVERAGE(O15,P15) -> 83.5 | R15: 12 | S15: 76 | T15: 76 | U15: =AVERAGE(S15,T15) -> 76 | V15: 12 | W15: 71 | X15: 71 | Y15: =AVERAGE(W15,X15) -> 71 | Z15: 12 | AA15: 76 | AB15: 78 | AC15: =AVERAGE(AA15,AB15) -> 77 | AD15: 12 | AE15: 95 | AF15: 95 | AG15: =AVERAGE(AE15,AF15) -> 95 | AH15: 12 | AI15: 90 | AJ15: 83 | AK15: =AVERAGE(AI15,AJ15) -> 86.5 | AL15: 12 | AM15: 72 | AN15: 63 | AO15: =AVERAGE(AM15,AN15) -> 67.5 | AP15: 12 | AQ15: 47 | AR15: 45 | AS15: =AVERAGE(AQ15,AR15) -> 46 | AT15: 12 | AU15: 49 | AV15: 46 | AW15: =AVERAGE(AU15,AV15) -> 47.5 | AY15: Décembre | AZ15: =AVERAGE(AW4:AW34) -> 66.709677
B16: 13 | C16: 77 | D16: 81 | E16: =AVERAGE(C16,D16) -> 79 | F16: 13 | G16: 88 | H16: 89 | I16: =AVERAGE(G16,H16) -> 88.5 | J16: 13 | K16: 82 | L16: 85 | M16: =AVERAGE(K16,L16) -> 83.5 | N16: 13 | O16: 85 | P16: 85 | Q16: =AVERAGE(O16,P16) -> 85 | R16: 13 | S16: 77 | T16: 76 | U16: =AVERAGE(S16,T16) -> 76.5 | V16: 13 | W16: 71 | X16: 71 | Y16: =AVERAGE(W16,X16) -> 71 | Z16: 13 | AA16: 80 | AB16: 81 | AC16: =AVERAGE(AA16,AB16) -> 80.5 | AD16: 13 | AE16: 93 | AF16: 90 | AG16: =AVERAGE(AE16,AF16) -> 91.5 | AH16: 13 | AI16: 75 | AJ16: 66 | AK16: =AVERAGE(AI16,AJ16) -> 70.5 | AL16: 13 | AM16: 55 | AN16: 47 | AO16: =AVERAGE(AM16,AN16) -> 51 | AP16: 13 | AQ16: 44 | AS16: =AVERAGE(AQ16,AR16) -> 44 | AT16: 13 | AU16: 45 | AW16: =AVERAGE(AU16,AV16) -> 45 | AY16: Coef total | AZ16: =AVERAGE(AZ4:AZ15) -> 66.636553
B17: 14 | C17: 83 | D17: 85 | E17: =AVERAGE(C17,D17) -> 84 | F17: 14 | G17: 90 | H17: 90 | I17: =AVERAGE(G17,H17) -> 90 | J17: 14 | K17: 88 | L17: 89 | M17: =AVERAGE(K17,L17) -> 88.5 | N17: 14 | O17: 85 | P17: 84 | Q17: =AVERAGE(O17,P17) -> 84.5 | R17: 14 | S17: 76 | T17: 74 | U17: =AVERAGE(S17,T17) -> 75 | V17: 14 | W17: 70 | X17: 70 | Y17: =AVERAGE(W17,X17) -> 70 | Z17: 14 | AA17: 81 | AB17: 81 | AC17: =AVERAGE(AA17,AB17) -> 81 | AD17: 14 | AE17: 86 | AF17: 81 | AG17: =AVERAGE(AE17,AF17) -> 83.5 | AH17: 14 | AI17: 58 | AJ17: 49 | AK17: =AVERAGE(AI17,AJ17) -> 53.5 | AL17: 14 | AM17: 41 | AO17: =AVERAGE(AM17,AN17) -> 41 | AP17: 14 | AQ17: 45 | AR17: 48 | AS17: =AVERAGE(AQ17,AR17) -> 46.5 | AT17: 14 | AU17: 44 | AV17: 45 | AW17: =AVERAGE(AU17,AV17) -> 44.5
B18: 15 | C18: 86 | D18: 86 | E18: =AVERAGE(C18,D18) -> 86 | F18: 15 | G18: 89 | H18: 87 | I18: =AVERAGE(G18,H18) -> 88 | J18: 15 | K18: 90 | L18: 90 | M18: =AVERAGE(K18,L18) -> 90 | N18: 15 | O18: 82 | P18: 80 | Q18: =AVERAGE(O18,P18) -> 81 | R18: 15 | S18: 73 | T18: 70 | U18: =AVERAGE(S18,T18) -> 71.5 | V18: 15 | W18: 68 | X18: 67 | Y18: =AVERAGE(W18,X18) -> 67.5 | Z18: 15 | AA18: 80 | AB18: 78 | AC18: =AVERAGE(AA18,AB18) -> 79 | AD18: 15 | AE18: 75 | AF18: 68 | AG18: =AVERAGE(AE18,AF18) -> 71.5 | AH18: 15 | AI18: 43 | AK18: =AVERAGE(AI18,AJ18) -> 43 | AL18: 15 | AM18: 39 | AN18: 40 | AO18: =AVERAGE(AM18,AN18) -> 39.5 | AP18: 15 | AQ18: 51 | AR18: 55 | AS18: =AVERAGE(AQ18,AR18) -> 53 | AT18: 15 | AU18: 47 | AV18: 49 | AW18: =AVERAGE(AU18,AV18) -> 48
B19: 16 | C19: 86 | D19: 85 | E19: =AVERAGE(C19,D19) -> 85.5 | F19: 16 | G19: 84 | H19: 80 | I19: =AVERAGE(G19,H19) -> 82 | J19: 16 | K19: 89 | L19: 88 | M19: =AVERAGE(K19,L19) -> 88.5 | N19: 16 | O19: 77 | P19: 73 | Q19: =AVERAGE(O19,P19) -> 75 | R19: 16 | S19: 68 | T19: 65 | U19: =AVERAGE(S19,T19) -> 66.5 | V19: 16 | W19: 65 | X19: 63 | Y19: =AVERAGE(W19,X19) -> 64 | Z19: 16 | AA19: 76 | AB19: 72 | AC19: =AVERAGE(AA19,AB19) -> 74 | AD19: 16 | AE19: 62 | AF19: 55 | AG19: =AVERAGE(AE19,AF19) -> 58.5 | AH19: 16 | AI19: 38 | AJ19: 38 | AK19: =AVERAGE(AI19,AJ19) -> 38 | AL19: 16 | AM19: 44 | AN19: 49 | AO19: =AVERAGE(AM19,AN19) -> 46.5 | AP19: 16 | AQ19: 59 | AR19: 62 | AS19: =AVERAGE(AQ19,AR19) -> 60.5 | AT19: 16 | AU19: 51 | AV19: 54 | AW19: =AVERAGE(AU19,AV19) -> 52.5
B20: 17 | C20: 83 | D20: 80 | E20: =AVERAGE(C20,D20) -> 81.5 | F20: 17 | G20: 76 | H20: 72 | I20: =AVERAGE(G20,H20) -> 74 | J20: 17 | K20: 86 | L20: 83 | M20: =AVERAGE(K20,L20) -> 84.5 | N20: 17 | O20: 69 | P20: 65 | Q20: =AVERAGE(O20,P20) -> 67 | R20: 17 | S20: 61 | T20: 58 | U20: =AVERAGE(S20,T20) -> 59.5 | V20: 17 | W20: 61 | X20: 59 | Y20: =AVERAGE(W20,X20) -> 60 | Z20: 17 | AA20: 69 | AB20: 65 | AC20: =AVERAGE(AA20,AB20) -> 67 | AD20: 17 | AE20: 49 | AG20: =AVERAGE(AE20,AF20) -> 49 | AH20: 17 | AI20: 41 | AJ20: 47 | AK20: =AVERAGE(AI20,AJ20) -> 44 | AL20: 17 | AM20: 55 | AN20: 61 | AO20: =AVERAGE(AM20,AN20) -> 58 | AP20: 17 | AQ20: 66 | AR20: 69 | AS20: =AVERAGE(AQ20,AR20) -> 67.5 | AT20: 17 | AU20: 57 | AV20: 60 | AW20: =AVERAGE(AU20,AV20) -> 58.5
B21: 18 | C21: 76 | D21: 72 | E21: =AVERAGE(C21,D21) -> 74 | F21: 18 | G21: 67 | H21: 61 | I21: =AVERAGE(G21,H21) -> 64 | J21: 18 | K21: 79 | L21: 75 | M21: =AVERAGE(K21,L21) -> 77 | N21: 18 | O21: 60 | P21: 54 | Q21: =AVERAGE(O21,P21) -> 57 | R21: 18 | S21: 54 | T21: 50 | U21: =AVERAGE(S21,T21) -> 52 | V21: 18 | W21: 58 | X21: 56 | Y21: =AVERAGE(W21,X21) -> 57 | Z21: 18 | AA21: 62 | AB21: 58 | AC21: =AVERAGE(AA21,AB21) -> 60 | AD21: 18 | AE21: 45 | AF21: 43 | AG21: =AVERAGE(AE21,AF21) -> 44 | AH21: 18 | AI21: 54 | AJ21: 61 | AK21: =AVERAGE(AI21,AJ21) -> 57.5 | AL21: 18 | AM21: 67 | AN21: 71 | AO21: =AVERAGE(AM21,AN21) -> 69 | AP21: 18 | AQ21: 71 | AR21: 73 | AS21: =AVERAGE(AQ21,AR21) -> 72 | AT21: 18 | AU21: 63 | AV21: 65 | AW21: =AVERAGE(AU21,AV21) -> 64
B22: 19 | C22: 68 | D22: 63 | E22: =AVERAGE(C22,D22) -> 65.5 | F22: 19 | G22: 56 | H22: 49 | I22: =AVERAGE(G22,H22) -> 52.5 | J22: 19 | K22: 70 | L22: 65 | M22: =AVERAGE(K22,L22) -> 67.5 | N22: 19 | O22: 49 | P22: 44 | Q22: =AVERAGE(O22,P22) -> 46.5 | R22: 19 | S22: 47 | T22: 45 | U22: =AVERAGE(S22,T22) -> 46 | V22: 19 | W22: 56 | Y22: =AVERAGE(W22,X22) -> 56 | Z22: 19 | AA22: 55 | AC22: =AVERAGE(AA22,AB22) -> 55 | AD22: 19 | AE22: 44 | AF22: 48 | AG22: =AVERAGE(AE22,AF22) -> 46 | AH22: 19 | AI22: 68 | AJ22: 74 | AK22: =AVERAGE(AI22,AJ22) -> 71 | AL22: 19 | AM22: 76 | AN22: 79 | AO22: =AVERAGE(AM22,AN22) -> 77.5 | AP22: 19 | AQ22: 75 | AR22: 76 | AS22: =AVERAGE(AQ22,AR22) -> 75.5 | AT22: 19 | AU22: 67 | AV22: 69 | AW22: =AVERAGE(AU22,AV22) -> 68
B23: 20 | C23: 59 | D23: 53 | E23: =AVERAGE(C23,D23) -> 56 | F23: 20 | G23: 44 | H23: 38 | I23: =AVERAGE(G23,H23) -> 41 | J23: 20 | K23: 59 | L23: 53 | M23: =AVERAGE(K23,L23) -> 56 | N23: 20 | O23: 39 | P23: 34 | Q23: =AVERAGE(O23,P23) -> 36.5 | R23: 20 | S23: 44 | T23: 44 | U23: =AVERAGE(S23,T23) -> 44 | V23: 20 | W23: 56 | X23: 57 | Y23: =AVERAGE(W23,X23) -> 56.5 | Z23: 20 | AA23: 53 | AB23: 52 | AC23: =AVERAGE(AA23,AB23) -> 52.5 | AD23: 20 | AE23: 54 | AF23: 60 | AG23: =AVERAGE(AE23,AF23) -> 57 | AH23: 20 | AI23: 79 | AJ23: 84 | AK23: =AVERAGE(AI23,AJ23) -> 81.5 | AL23: 20 | AM23: 82 | AN23: 84 | AO23: =AVERAGE(AM23,AN23) -> 83 | AP23: 20 | AQ23: 77 | AR23: 77 | AS23: =AVERAGE(AQ23,AR23) -> 77 | AT23: 20 | AU23: 71 | AV23: 72 | AW23: =AVERAGE(AU23,AV23) -> 71.5
B24: 21 | C24: 48 | D24: 43 | E24: =AVERAGE(C24,D24) -> 45.5 | F24: 21 | G24: 32 | H24: 28 | I24: =AVERAGE(G24,H24) -> 30 | J24: 21 | K24: 47 | L24: 41 | M24: =AVERAGE(K24,L24) -> 44 | N24: 21 | O24: 32 | Q24: =AVERAGE(O24,P24) -> 32 | R24: 21 | S24: 46 | U24: =AVERAGE(S24,T24) -> 46 | V24: 21 | W24: 58 | X24: 61 | Y24: =AVERAGE(W24,X24) -> 59.5 | Z24: 21 | AA24: 53 | AB24: 56 | AC24: =AVERAGE(AA24,AB24) -> 54.5 | AD24: 21 | AE24: 67 | AF24: 73 | AG24: =AVERAGE(AE24,AF24) -> 70 | AH24: 21 | AI24: 87 | AJ24: 89 | AK24: =AVERAGE(AI24,AJ24) -> 88 | AL24: 21 | AM24: 85 | AN24: 86 | AO24: =AVERAGE(AM24,AN24) -> 85.5 | AP24: 21 | AQ24: 76 | AR24: 76 | AS24: =AVERAGE(AQ24,AR24) -> 76 | AT24: 21 | AU24: 73 | AV24: 73 | AW24: =AVERAGE(AU24,AV24) -> 73
B25: 22 | C25: 39 | D25: 35 | E25: =AVERAGE(C25,D25) -> 37 | F25: 22 | G25: 25 | I25: =AVERAGE(G25,H25) -> 25 | J25: 22 | K25: 35 | L25: 29 | M25: =AVERAGE(K25,L25) -> 32 | N25: 22 | O25: 32 | P25: 35 | Q25: =AVERAGE(O25,P25) -> 33.5 | R25: 22 | S25: 49 | T25: 54 | U25: =AVERAGE(S25,T25) -> 51.5 | V25: 22 | W25: 64 | X25: 67 | Y25: =AVERAGE(W25,X25) -> 65.5 | Z25: 22 | AA25: 59 | AB25: 64 | AC25: =AVERAGE(AA25,AB25) -> 61.5 | AD25: 22 | AE25: 78 | AF25: 83 | AG25: =AVERAGE(AE25,AF25) -> 80.5 | AH25: 22 | AI25: 91 | AJ25: 91 | AK25: =AVERAGE(AI25,AJ25) -> 91 | AL25: 22 | AM25: 86 | AN25: 85 | AO25: =AVERAGE(AM25,AN25) -> 85.5 | AP25: 22 | AQ25: 74 | AR25: 73 | AS25: =AVERAGE(AQ25,AR25) -> 73.5 | AT25: 22 | AU25: 73 | AV25: 73 | AW25: =AVERAGE(AU25,AV25) -> 73
B26: 23 | C26: 32 | E26: =AVERAGE(C26,D26) -> 32 | F26: 23 | G26: 26 | H26: 30 | I26: =AVERAGE(G26,H26) -> 28 | J26: 23 | K26: 26 | L26: 26 | M26: =AVERAGE(K26,L26) -> 26 | N26: 23 | O26: 41 | P26: 48 | Q26: =AVERAGE(O26,P26) -> 44.5 | R26: 23 | S26: 59 | T26: 65 | U26: =AVERAGE(S26,T26) -> 62 | V26: 23 | W26: 71 | X26: 75 | Y26: =AVERAGE(W26,X26) -> 73 | Z26: 23 | AA26: 69 | AB26: 73 | AC26: =AVERAGE(AA26,AB26) -> 71 | AD26: 23 | AE26: 87 | AF26: 89 | AG26: =AVERAGE(AE26,AF26) -> 88 | AH26: 23 | AI26: 91 | AJ26: 90 | AK26: =AVERAGE(AI26,AJ26) -> 90.5 | AL26: 23 | AM26: 83 | AN26: 81 | AO26: =AVERAGE(AM26,AN26) -> 82 | AP26: 23 | AQ26: 70 | AR26: 68 | AS26: =AVERAGE(AQ26,AR26) -> 69 | AT26: 23 | AU26: 72 | AV26: 71 | AW26: =AVERAGE(AU26,AV26) -> 71.5
B27: 24 | C27: 31 | D27: 31 | E27: =AVERAGE(C27,D27) -> 31 | F27: 24 | G27: 36 | H27: 44 | I27: =AVERAGE(G27,H27) -> 40 | J27: 24 | K27: 29 | M27: =AVERAGE(K27,L27) -> 29 | N27: 24 | O27: 57 | P27: 65 | Q27: =AVERAGE(O27,P27) -> 61 | R27: 24 | S27: 71 | T27: 77 | U27: =AVERAGE(S27,T27) -> 74 | V27: 24 | W27: 78 | X27: 82 | Y27: =AVERAGE(W27,X27) -> 80 | Z27: 24 | AA27: 78 | AB27: 82 | AC27: =AVERAGE(AA27,AB27) -> 80 | AD27: 24 | AE27: 91 | AF27: 92 | AG27: =AVERAGE(AE27,AF27) -> 91.5 | AH27: 24 | AI27: 88 | AJ27: 86 | AK27: =AVERAGE(AI27,AJ27) -> 87 | AL27: 24 | AM27: 79 | AN27: 76 | AO27: =AVERAGE(AM27,AN27) -> 77.5 | AP27: 24 | AQ27: 65 | AR27: 62 | AS27: =AVERAGE(AQ27,AR27) -> 63.5 | AT27: 24 | AU27: 70 | AV27: 68 | AW27: =AVERAGE(AU27,AV27) -> 69
B28: 25 | C28: 34 | D28: 37 | E28: =AVERAGE(C28,D28) -> 35.5 | F28: 25 | G28: 52 | H28: 60 | I28: =AVERAGE(G28,H28) -> 56 | J28: 25 | K28: 36 | L28: 44 | M28: =AVERAGE(K28,L28) -> 40 | N28: 25 | O28: 74 | P28: 82 | Q28: =AVERAGE(O28,P28) -> 78 | R28: 25 | S28: 83 | T28: 88 | U28: =AVERAGE(S28,T28) -> 85.5 | V28: 25 | W28: 84 | X28: 86 | Y28: =AVERAGE(W28,X28) -> 85 | Z28: 25 | AA28: 85 | AB28: 87 | AC28: =AVERAGE(AA28,AB28) -> 86 | AD28: 25 | AE28: 92 | AF28: 91 | AG28: =AVERAGE(AE28,AF28) -> 91.5 | AH28: 25 | AI28: 82 | AJ28: 78 | AK28: =AVERAGE(AI28,AJ28) -> 80 | AL28: 25 | AM28: 72 | AN28: 68 | AO28: =AVERAGE(AM28,AN28) -> 70 | AP28: 25 | AQ28: 59 | AR28: 55 | AS28: =AVERAGE(AQ28,AR28) -> 57 | AT28: 25 | AU28: 66 | AV28: 64 | AW28: =AVERAGE(AU28,AV28) -> 65
B29: 26 | C29: 43 | D29: 48 | E29: =AVERAGE(C29,D29) -> 45.5 | F29: 26 | G29: 69 | H29: 77 | I29: =AVERAGE(G29,H29) -> 73 | J29: 26 | K29: 54 | L29: 63 | M29: =AVERAGE(K29,L29) -> 58.5 | N29: 26 | O29: 90 | P29: 96 | Q29: =AVERAGE(O29,P29) -> 93 | R29: 26 | S29: 92 | T29: 94 | U29: =AVERAGE(S29,T29) -> 93 | V29: 26 | W29: 87 | X29: 88 | Y29: =AVERAGE(W29,X29) -> 87.5 | Z29: 26 | AA29: 89 | AB29: 89 | AC29: =AVERAGE(AA29,AB29) -> 89 | AD29: 26 | AE29: 89 | AF29: 86 | AG29: =AVERAGE(AE29,AF29) -> 87.5 | AH29: 26 | AI29: 74 | AJ29: 69 | AK29: =AVERAGE(AI29,AJ29) -> 71.5 | AL29: 26 | AM29: 63 | AN29: 59 | AO29: =AVERAGE(AM29,AN29) -> 61 | AP29: 26 | AQ29: 52 | AR29: 49 | AS29: =AVERAGE(AQ29,AR29) -> 50.5 | AT29: 26 | AU29: 61 | AV29: 59 | AW29: =AVERAGE(AU29,AV29) -> 60
B30: 27 | C30: 55 | D30: 61 | E30: =AVERAGE(C30,D30) -> 58 | F30: 27 | G30: 85 | H30: 92 | I30: =AVERAGE(G30,H30) -> 88.5 | J30: 27 | K30: 73 | L30: 82 | M30: =AVERAGE(K30,L30) -> 77.5 | N30: 27 | O30: 101 | P30: 105 | Q30: =AVERAGE(O30,P30) -> 103 | R30: 27 | S30: 96 | T30: 97 | U30: =AVERAGE(S30,T30) -> 96.5 | V30: 27 | W30: 88 | X30: 86 | Y30: =AVERAGE(W30,X30) -> 87 | Z30: 27 | AA30: 89 | AB30: 87 | AC30: =AVERAGE(AA30,AB30) -> 88 | AD30: 27 | AE30: 82 | AF30: 78 | AG30: =AVERAGE(AE30,AF30) -> 80 | AH30: 27 | AI30: 63 | AJ30: 58 | AK30: =AVERAGE(AI30,AJ30) -> 60.5 | AL30: 27 | AM30: 53 | AN30: 48 | AO30: =AVERAGE(AM30,AN30) -> 50.5 | AP30: 27 | AQ30: 46 | AR30: 44 | AS30: =AVERAGE(AQ30,AR30) -> 45 | AT30: 27 | AU30: 57 | AV30: 55 | AW30: =AVERAGE(AU30,AV30) -> 56
B31: 28 | C31: 67 | D31: 73 | E31: =AVERAGE(C31,D31) -> 70 | F31: 28 | G31: 99 | H31: 104 | I31: =AVERAGE(G31,H31) -> 101.5 | J31: 28 | K31: 90 | L31: 97 | M31: =AVERAGE(K31,L31) -> 93.5 | N31: 28 | O31: 108 | P31: 108 | Q31: =AVERAGE(O31,P31) -> 108 | R31: 28 | S31: 96 | T31: 95 | U31: =AVERAGE(S31,T31) -> 95.5 | V31: 28 | W31: 85 | X31: 82 | Y31: =AVERAGE(W31,X31) -> 83.5 | Z31: 28 | AA31: 85 | AB31: 82 | AC31: =AVERAGE(AA31,AB31) -> 83.5 | AD31: 28 | AE31: 73 | AF31: 68 | AG31: =AVERAGE(AE31,AF31) -> 70.5 | AH31: 28 | AI31: 52 | AJ31: 46 | AK31: =AVERAGE(AI31,AJ31) -> 49 | AL31: 28 | AM31: 43 | AN31: 38 | AO31: =AVERAGE(AM31,AN31) -> 40.5 | AP31: 28 | AQ31: 43 | AR31: 43 | AS31: =AVERAGE(AQ31,AR31) -> 43 | AT31: 28 | AU31: 53 | AV31: 52 | AW31: =AVERAGE(AU31,AV31) -> 52.5
B32: 29 | C32: 79 | D32: 84 | E32: =AVERAGE(C32,D32) -> 81.5 | J32: 29 | K32: 104 | L32: 109 | M32: =AVERAGE(K32,L32) -> 106.5 | N32: 29 | O32: 107 | P32: 105 | Q32: =AVERAGE(O32,P32) -> 106 | R32: 29 | S32: 92 | T32: 89 | U32: =AVERAGE(S32,T32) -> 90.5 | V32: 29 | W32: 79 | X32: 75 | Y32: =AVERAGE(W32,X32) -> 77 | Z32: 29 | AA32: 78 | AB32: 74 | AC32: =AVERAGE(AA32,AB32) -> 76 | AD32: 29 | AE32: 62 | AF32: 56 | AG32: =AVERAGE(AE32,AF32) -> 59 | AH32: 29 | AI32: 39 | AJ32: 33 | AK32: =AVERAGE(AI32,AJ32) -> 36 | AL32: 29 | AM32: 34 | AN32: 31 | AO32: =AVERAGE(AM32,AN32) -> 32.5 | AP32: 29 | AQ32: 45 | AS32: =AVERAGE(AQ32,AR32) -> 45 | AT32: 29 | AU32: 53 | AW32: =AVERAGE(AU32,AV32) -> 53
B33: 30 | C33: 89 | D33: 93 | E33: =AVERAGE(C33,D33) -> 91 | J33: 30 | K33: 112 | L33: 114 | M33: =AVERAGE(K33,L33) -> 113 | N33: 30 | O33: 101 | P33: 96 | Q33: =AVERAGE(O33,P33) -> 98.5 | R33: 30 | S33: 84 | T33: 79 | U33: =AVERAGE(S33,T33) -> 81.5 | V33: 30 | W33: 71 | X33: 67 | Y33: =AVERAGE(W33,X33) -> 69 | Z33: 30 | AA33: 69 | AB33: 64 | AC33: =AVERAGE(AA33,AB33) -> 66.5 | AD33: 30 | AE33: 50 | AF33: 44 | AG33: =AVERAGE(AE33,AF33) -> 47 | AH33: 30 | AI33: 28 | AJ33: 25 | AK33: =AVERAGE(AI33,AJ33) -> 26.5 | AL33: 30 | AM33: 31 | AN33: 33 | AO33: =AVERAGE(AM33,AN33) -> 32 | AP33: 30 | AQ33: 48 | AR33: 53 | AS33: =AVERAGE(AQ33,AR33) -> 50.5 | AT33: 30 | AU33: 54 | AV33: 56 | AW33: =AVERAGE(AU33,AV33) -> 55
B34: 31 | C34: 96 | D34: 98 | E34: =AVERAGE(C34,D34) -> 97 | J34: 31 | K34: 114 | L34: 111 | M34: =AVERAGE(K34,L34) -> 112.5 | R34: 31 | S34: 74 | T34: 69 | U34: =AVERAGE(S34,T34) -> 71.5 | Z34: 31 | AA34: 58 | AB34: 53 | AC34: =AVERAGE(AA34,AB34) -> 55.5 | AD34: 31 | AE34: 37 | AF34: 32 | AG34: =AVERAGE(AE34,AF34) -> 34.5 | AL34: 31 | AM34: 38 | AO34: =AVERAGE(AM34,AN34) -> 38 | AT34: 31 | AU34: 60 | AV34: 64 | AW34: =AVERAGE(AU34,AV34) -> 62
B37: 45658 | N37: 45689 | Z37: 45717 | AL37: 45748 | AX37: 45778 | BG37: 45809 | BP37: 45839
C38: 01 M | D38: Jour de l'an | J38: 80 | K38: 81 | O38: 01 S | P38: Ella | V38: 99 | W38: 98 | AA38: 01 S | AB38: Aubin | AH38: 108 | AI38: 110 | AM38: 01 M | AN38: Hugues | AT38: 107 | AU38: 102 | AY38: 01 J | AZ38: Fête du travail | BD38: 89 | BE38: 82 | BH38: 01 D | BI38: Justin | BM38: 63 | BN38: 58 | BQ38: 01 M | BR38: Thierry | BV38: 62 | BW38: 57
C39: 02 J | D39: Basile | J39: 82 | K39: 83 | O39: 02 D | P39: Pré. du S. | V39: 96 | W39: 93 | AA39: 02 D | AB39: Charles le Bon | AH39: 111 | AI39: 109 | AM39: 02 M | AN39: Sandrine | AT39: 95 | AU39: 87 | AY39: 02 V | AZ39: Boris | BD39: 74 | BE39: 66 | BH39: 02 L | BI39: Blandine | BM39: 53 | BN39: 49 | BQ39: 02 M | BR39: Martinien | BV39: 53 | BW39: 49
C40: 03 V | D40: Geneviève | J40: 82 | K40: 81 | O40: 03 L | P40: Blaise | V40: 89 | W40: 84 | AA40: 03 L | AB40: Guénolé | AH40: 107 | AI40: 102 | AM40: 03 J | AN40: Richard | AT40: 77 | AU40: 68 | AY40: 03 S | AZ40: Philippe; Jacques | BD40: 58 | BE40: 51 | BH40: 03 M | BI40: Kévin | BM40: 46 | BQ40: 03 J | BR40: Thomas | BV40: 45
C41: 04 S | D41: Odilon | J41: 80 | K41: 78 | O41: 04 M | P41: Véronique | V41: 78 | W41: 71 | AA41: 04 M | AB41: Casimir | AH41: 96 | AI41: 89 | AM41: 04 V | AN41: Isidore | AT41: 58 | AU41: 50 | AY41: 04 D | AZ41: Sylvain | BD41: 45 | BE41: 42 | BH41: 04 M | BI41: Clotilde | BM41: 44 | BN41: 43 | BQ41: 04 V | BR41: Florent | BV41: 42 | BW41: 39
C42: 05 D | D42: Edouard | J42: 75 | K42: 72 | O42: 05 M | P42: Agathe | V42: 64 | W42: 57 | AA42: 05 M | AB42: Olive | AH42: 80 | AI42: 72 | AM42: 05 S | AN42: Irène | AT42: 42 | AU42: 37 | AY42: 05 L | AZ42: Judith | BD42: 40 | BH42: 05 J | BI42: Igor | BM42: 43 | BN42: 44 | BQ42: 05 S | BR42: Antoine | BV42: 38 | BW42: 38
...

Sheet Etude du point -4,82 Lat 48,34
A1: Longitude | B1: Lattitude | C1: Vitesse moyenne zone morte (m/s) | D1: Vitesse moyenne eaux vives (m/s) | E1: Vc (m/s) | F1: Puissance cinétique (w) | G1: Energie annuel (kw/h)
A2: -4.82438 | B2: 48.3393 | C2: 0.86575941 | D2: 1.700307 | E2: =C2+(($P$3-45)/50*(D2-C2)) -> 1.700307 | F2: =(1/2)*$Q$3*$S$3*(E2^3) -> 197763.23 | G2: =C2+(($P$3-45)/50*(D2-C2)) -> 1.700307 | P2: Coefficient de marée | Q2: Densité de l'eau salée | R2: Rayon du rotor | S2: Surface du rotor | V2: Janvier | X2: Février | Z2: Mars | AB2: Avril | AD2: Mai | AF2: Juin | AH2: Juillet | AJ2: Août | AL2: Septembre | AN2: Octobre | AP2: Novembre | AR2: Décembre
P3: 95 | Q3: 1025 | R3: 5 | S3: =(R3^2)*3.14 -> 78.5 | V3: Vitesse moyenne du jour | W3: Energie produite journalière (kw/h) | X3: Vitesse moyenne du jour | Y3: Energie produite journalière (kw/h) | Z3: Vitesse moyenne du jour | AA3: Energie produite journalière (kw/h) | AB3: Vitesse moyenne du jour | AC3: Energie produite journalière (kw/h) | AD3: Vitesse moyenne du jour | AE3: Energie produite journalière (kw/h) | AF3: Vitesse moyenne du jour | AG3: Energie produite journalière (kw/h) | AH3: Vitesse moyenne du jour | AI3: Energie produite journalière (kw/h) | AJ3: Vitesse moyenne du jour | AK3: Energie produite journalière (kw/h) | AL3: Vitesse moyenne du jour | AM3: Energie produite journalière (kw/h) | AN3: Vitesse moyenne du jour | AO3: Energie produite journalière (kw/h) | AP3: Vitesse moyenne du jour | AQ3: Energie produite journalière (kw/h) | AR3: Vitesse moyenne du jour | AS3: Energie produite journalière (kw/h)
V4: =$C$2+(('Coefficient de marée'!E4-45)/50*($D$2-$C$2)) -> 1.4582882 | W4: =(1/2)*$Q$3*$S$3*(V4^3)*24/1000 -> 2994.3658 | X4: =$C$2+(('Coefficient de marée'!I4-45)/50*($D$2-$C$2)) -> 1.7587253 | Y4: =(1/2)*$Q$3*$S$3*(X4^3)*24/1000 -> 5252.5334 | Z4: =$C$2+(('Coefficient de marée'!M4-45)/50*($D$2-$C$2)) -> 1.9339803 | AA4: =(1/2)*$Q$3*$S$3*(Z4^3)*24/1000 -> 6984.4292 | AB4: =$C$2+(('Coefficient de marée'!Q4-45)/50*($D$2-$C$2)) -> 1.858871 | AC4: =(1/2)*$Q$3*$S$3*(AB4^3)*24/1000 -> 6201.8685 | AD4: =$C$2+(('Coefficient de marée'!U4-45)/50*($D$2-$C$2)) -> 1.541743 | AE4: =(1/2)*$Q$3*$S$3*(AD4^3)*24/1000 -> 3538.4307 | AF4: =$C$2+(('Coefficient de marée'!Y4-45)/50*($D$2-$C$2)) -> 1.1244692 | AG4: =(1/2)*$Q$3*$S$3*(AF4^3)*24/1000 -> 1372.8321 | AH4: =$C$2+(('Coefficient de marée'!AC4-45)/50*($D$2-$C$2)) -> 1.1077782 | AI4: =(1/2)*$Q$3*$S$3*(AH4^3)*24/1000 -> 1312.6025 | AJ4: =$C$2+(('Coefficient de marée'!AG4-45)/50*($D$2-$C$2)) -> 0.85741394 | AK4: =(1/2)*$Q$3*$S$3*(AJ4^3)*24/1000 -> 608.62023 | AL4: =$C$2+(('Coefficient de marée'!AK4-45)/50*($D$2-$C$2)) -> 0.56532228 | AM4: =(1/2)*$Q$3*$S$3*(AL4^3)*24/1000 -> 174.44683 | AN4: =$C$2+(('Coefficient de marée'!AO4-45)/50*($D$2-$C$2)) -> 0.51524943 | AO4: =(1/2)*$Q$3*$S$3*(AN4^3)*24/1000 -> 132.07704 | AP4: =$C$2+(('Coefficient de marée'!AS4-45)/50*($D$2-$C$2)) -> 0.91583227 | AQ4: =(1/2)*$Q$3*$S$3*(AP4^3)*24/1000 -> 741.69029 | AR4: =$C$2+(('Coefficient de marée'!AW4-45)/50*($D$2-$C$2)) -> 1.1328146 | AS4: =(1/2)*$Q$3*$S$3*(AR4^3)*24/1000 -> 1403.6258
V5: =$C$2+(('Coefficient de marée'!E5-45)/50*($D$2-$C$2)) -> 1.4916701 | W5: =(1/2)*$Q$3*$S$3*(V5^3)*24/1000 -> 3204.7424 | X5: =$C$2+(('Coefficient de marée'!I5-45)/50*($D$2-$C$2)) -> 1.6919615 | Y5: =(1/2)*$Q$3*$S$3*(X5^3)*24/1000 -> 4676.7722 | Z5: =$C$2+(('Coefficient de marée'!M5-45)/50*($D$2-$C$2)) -> 1.9506713 | AA5: =(1/2)*$Q$3*$S$3*(Z5^3)*24/1000 -> 7166.8289 | AB5: =$C$2+(('Coefficient de marée'!Q5-45)/50*($D$2-$C$2)) -> 1.6335432 | AC5: =(1/2)*$Q$3*$S$3*(AB5^3)*24/1000 -> 4208.8809 | AD5: =$C$2+(('Coefficient de marée'!U5-45)/50*($D$2-$C$2)) -> 1.2830332 | AE5: =(1/2)*$Q$3*$S$3*(AD5^3)*24/1000 -> 2039.3345 | AF5: =$C$2+(('Coefficient de marée'!Y5-45)/50*($D$2-$C$2)) -> 0.96590512 | AG5: =(1/2)*$Q$3*$S$3*(AF5^3)*24/1000 -> 870.11805 | AH5: =$C$2+(('Coefficient de marée'!AC5-45)/50*($D$2-$C$2)) -> 0.96590512 | AI5: =(1/2)*$Q$3*$S$3*(AH5^3)*24/1000 -> 870.11805 | AJ5: =$C$2+(('Coefficient de marée'!AG5-45)/50*($D$2-$C$2)) -> 0.6988499 | AK5: =(1/2)*$Q$3*$S$3*(AJ5^3)*24/1000 -> 329.55392 | AL5: =$C$2+(('Coefficient de marée'!AK5-45)/50*($D$2-$C$2)) -> 0.51524943 | AM5: =(1/2)*$Q$3*$S$3*(AL5^3)*24/1000 -> 132.07704 | AN5: =$C$2+(('Coefficient de marée'!AO5-45)/50*($D$2-$C$2)) -> 0.63208609 | AO5: =(1/2)*$Q$3*$S$3*(AN5^3)*24/1000 -> 243.83917 | AP5: =$C$2+(('Coefficient de marée'!AS5-45)/50*($D$2-$C$2)) -> 1.1828875 | AQ5: =(1/2)*$Q$3*$S$3*(AP5^3)*24/1000 -> 1598.1042 | AR5: =$C$2+(('Coefficient de marée'!AW5-45)/50*($D$2-$C$2)) -> 1.3331061 | AS5: =(1/2)*$Q$3*$S$3*(AR5^3)*24/1000 -> 2287.541
V6: =$C$2+(('Coefficient de marée'!E6-45)/50*($D$2-$C$2)) -> 1.4749792 | W6: =(1/2)*$Q$3*$S$3*(V6^3)*24/1000 -> 3098.3638 | X6: =$C$2+(('Coefficient de marée'!I6-45)/50*($D$2-$C$2)) -> 1.5584339 | Y6: =(1/2)*$Q$3*$S$3*(X6^3)*24/1000 -> 3654.6007 | Z6: =$C$2+(('Coefficient de marée'!M6-45)/50*($D$2-$C$2)) -> 1.858871 | AA6: =(1/2)*$Q$3*$S$3*(Z6^3)*24/1000 -> 6201.8685 | AB6: =$C$2+(('Coefficient de marée'!Q6-45)/50*($D$2-$C$2)) -> 1.3247606 | AC6: =(1/2)*$Q$3*$S$3*(AB6^3)*24/1000 -> 2244.8481 | AD6: =$C$2+(('Coefficient de marée'!U6-45)/50*($D$2-$C$2)) -> 1.0243235 | AE6: =(1/2)*$Q$3*$S$3*(AD6^3)*24/1000 -> 1037.7342 | AF6: =$C$2+(('Coefficient de marée'!Y6-45)/50*($D$2-$C$2)) -> 0.88245037 | AG6: =(1/2)*$Q$3*$S$3*(AF6^3)*24/1000 -> 663.50718 | AH6: =$C$2+(('Coefficient de marée'!AC6-45)/50*($D$2-$C$2)) -> 0.86575941 | AI6: =(1/2)*$Q$3*$S$3*(AH6^3)*24/1000 -> 626.56544 | AJ6: =$C$2+(('Coefficient de marée'!AG6-45)/50*($D$2-$C$2)) -> 0.61539514 | AK6: =(1/2)*$Q$3*$S$3*(AJ6^3)*24/1000 -> 225.0282 | AL6: =$C$2+(('Coefficient de marée'!AK6-45)/50*($D$2-$C$2)) -> 0.63208609 | AM6: =(1/2)*$Q$3*$S$3*(AL6^3)*24/1000 -> 243.83917 | AN6: =$C$2+(('Coefficient de marée'!AO6-45)/50*($D$2-$C$2)) -> 0.88245037 | AO6: =(1/2)*$Q$3*$S$3*(AN6^3)*24/1000 -> 663.50718 | AP6: =$C$2+(('Coefficient de marée'!AS6-45)/50*($D$2-$C$2)) -> 1.4499427 | AQ6: =(1/2)*$Q$3*$S$3*(AP6^3)*24/1000 -> 2943.2511 | AR6: =$C$2+(('Coefficient de marée'!AW6-45)/50*($D$2-$C$2)) -> 1.525052 | AS6: =(1/2)*$Q$3*$S$3*(AR6^3)*24/1000 -> 3424.7489
V7: =$C$2+(('Coefficient de marée'!E7-45)/50*($D$2-$C$2)) -> 1.4332518 | W7: =(1/2)*$Q$3*$S$3*(V7^3)*24/1000 -> 2842.7733 | X7: =$C$2+(('Coefficient de marée'!I7-45)/50*($D$2-$C$2)) -> 1.3581425 | Y7: =(1/2)*$Q$3*$S$3*(X7^3)*24/1000 -> 2418.8602 | Z7: =$C$2+(('Coefficient de marée'!M7-45)/50*($D$2-$C$2)) -> 1.6585796 | AA7: =(1/2)*$Q$3*$S$3*(Z7^3)*24/1000 -> 4405.3837 | AB7: =$C$2+(('Coefficient de marée'!Q7-45)/50*($D$2-$C$2)) -> 1.015978 | AC7: =(1/2)*$Q$3*$S$3*(AB7^3)*24/1000 -> 1012.5761 | AD7: =$C$2+(('Coefficient de marée'!U7-45)/50*($D$2-$C$2)) -> 0.84072299 | AE7: =(1/2)*$Q$3*$S$3*(AD7^3)*24/1000 -> 573.76431 | AF7: =$C$2+(('Coefficient de marée'!Y7-45)/50*($D$2-$C$2)) -> 0.84072299 | AG7: =(1/2)*$Q$3*$S$3*(AF7^3)*24/1000 -> 573.76431 | AH7: =$C$2+(('Coefficient de marée'!AC7-45)/50*($D$2-$C$2)) -> 0.79065013 | AI7: =(1/2)*$Q$3*$S$3*(AH7^3)*24/1000 -> 477.23008 | AJ7: =$C$2+(('Coefficient de marée'!AG7-45)/50*($D$2-$C$2)) -> 0.61539514 | AK7: =(1/2)*$Q$3*$S$3*(AJ7^3)*24/1000 -> 225.0282 | AL7: =$C$2+(('Coefficient de marée'!AK7-45)/50*($D$2-$C$2)) -> 0.86575941 | AM7: =(1/2)*$Q$3*$S$3*(AL7^3)*24/1000 -> 626.56544 | AN7: =$C$2+(('Coefficient de marée'!AO7-45)/50*($D$2-$C$2)) -> 1.174542 | AO7: =(1/2)*$Q$3*$S$3*(AN7^3)*24/1000 -> 1564.5176 | AP7: =$C$2+(('Coefficient de marée'!AS7-45)/50*($D$2-$C$2)) -> 1.6669251 | AQ7: =(1/2)*$Q$3*$S$3*(AP7^3)*24/1000 -> 4472.2186 | AR7: =$C$2+(('Coefficient de marée'!AW7-45)/50*($D$2-$C$2)) -> 1.6585796 | AS7: =(1/2)*$Q$3*$S$3*(AR7^3)*24/1000 -> 4405.3837
V8: =$C$2+(('Coefficient de marée'!E8-45)/50*($D$2-$C$2)) -> 1.3414515 | W8: =(1/2)*$Q$3*$S$3*(V8^3)*24/1000 -> 2330.7717 | X8: =$C$2+(('Coefficient de marée'!I8-45)/50*($D$2-$C$2)) -> 1.1244692 | Y8: =(1/2)*$Q$3*$S$3*(X8^3)*24/1000 -> 1372.8321 | Z8: =$C$2+(('Coefficient de marée'!M8-45)/50*($D$2-$C$2)) -> 1.3831789 | AA8: =(1/2)*$Q$3*$S$3*(Z8^3)*24/1000 -> 2555.1115 | AB8: =$C$2+(('Coefficient de marée'!Q8-45)/50*($D$2-$C$2)) -> 0.77395918 | AC8: =(1/2)*$Q$3*$S$3*(AB8^3)*24/1000 -> 447.64005 | AD8: =$C$2+(('Coefficient de marée'!U8-45)/50*($D$2-$C$2)) -> 0.78230465 | AE8: =(1/2)*$Q$3*$S$3*(AD8^3)*24/1000 -> 462.27724 | AF8: =$C$2+(('Coefficient de marée'!Y8-45)/50*($D$2-$C$2)) -> 0.84072299 | AG8: =(1/2)*$Q$3*$S$3*(AF8^3)*24/1000 -> 573.76431 | AH8: =$C$2+(('Coefficient de marée'!AC8-45)/50*($D$2-$C$2)) -> 0.74892275 | AI8: =(1/2)*$Q$3*$S$3*(AH8^3)*24/1000 -> 405.58869 | AJ8: =$C$2+(('Coefficient de marée'!AG8-45)/50*($D$2-$C$2)) -> 0.71554085 | AK8: =(1/2)*$Q$3*$S$3*(AJ8^3)*24/1000 -> 353.73502 | AL8: =$C$2+(('Coefficient de marée'!AK8-45)/50*($D$2-$C$2)) -> 1.1244692 | AM8: =(1/2)*$Q$3*$S$3*(AL8^3)*24/1000 -> 1372.8321 | AN8: =$C$2+(('Coefficient de marée'!AO8-45)/50*($D$2-$C$2)) -> 1.4499427 | AO8: =(1/2)*$Q$3*$S$3*(AN8^3)*24/1000 -> 2943.2511 | AP8: =$C$2+(('Coefficient de marée'!AS8-45)/50*($D$2-$C$2)) -> 1.8254891 | AQ8: =(1/2)*$Q$3*$S$3*(AP8^3)*24/1000 -> 5873.7104 | AR8: =$C$2+(('Coefficient de marée'!AW8-45)/50*($D$2-$C$2)) -> 1.7420344 | AS8: =(1/2)*$Q$3*$S$3*(AR8^3)*24/1000 -> 5104.4027
A9: Cette feuille à pour but de calculer l'énergie produite de manière journalière, mensuel, et annuel en tracant la courbe de production.Pour cela il faut importé les valeurs du points en case A2 à D2 disponible dans la feuille "Calcul puissance cinétique" | V9: =$C$2+(('Coefficient de marée'!E9-45)/50*($D$2-$C$2)) -> 1.2162694 | W9: =(1/2)*$Q$3*$S$3*(V9^3)*24/1000 -> 1737.2572 | X9: =$C$2+(('Coefficient de marée'!I9-45)/50*($D$2-$C$2)) -> 0.91583227 | Y9: =(1/2)*$Q$3*$S$3*(X9^3)*24/1000 -> 741.69029 | Z9: =$C$2+(('Coefficient de marée'!M9-45)/50*($D$2-$C$2)) -> 1.0743963 | AA9: =(1/2)*$Q$3*$S$3*(Z9^3)*24/1000 -> 1197.4801 | AB9: =$C$2+(('Coefficient de marée'!Q9-45)/50*($D$2-$C$2)) -> 0.6988499 | AC9: =(1/2)*$Q$3*$S$3*(AB9^3)*24/1000 -> 329.55392 | AD9: =$C$2+(('Coefficient de marée'!U9-45)/50*($D$2-$C$2)) -> 0.80734108 | AE9: =(1/2)*$Q$3*$S$3*(AD9^3)*24/1000 -> 508.09618 | AF9: =$C$2+(('Coefficient de marée'!Y9-45)/50*($D$2-$C$2)) -> 0.89914132 | AG9: =(1/2)*$Q$3*$S$3*(AF9^3)*24/1000 -> 701.87316 | AH9: =$C$2+(('Coefficient de marée'!AC9-45)/50*($D$2-$C$2)) -> 0.78230465 | AI9: =(1/2)*$Q$3*$S$3*(AH9^3)*24/1000 -> 462.27724 | AJ9: =$C$2+(('Coefficient de marée'!AG9-45)/50*($D$2-$C$2)) -> 0.88245037 | AK9: =(1/2)*$Q$3*$S$3*(AJ9^3)*24/1000 -> 663.50718 | AL9: =$C$2+(('Coefficient de marée'!AK9-45)/50*($D$2-$C$2)) -> 1.3831789 | AM9: =(1/2)*$Q$3*$S$3*(AL9^3)*24/1000 -> 2555.1115 | AN9: =$C$2+(('Coefficient de marée'!AO9-45)/50*($D$2-$C$2)) -> 1.6919615 | AO9: =(1/2)*$Q$3*$S$3*(AN9^3)*24/1000 -> 4676.7722 | AP9: =$C$2+(('Coefficient de marée'!AS9-45)/50*($D$2-$C$2)) -> 1.8839075 | AQ9: =(1/2)*$Q$3*$S$3*(AP9^3)*24/1000 -> 6455.8506 | AR9: =$C$2+(('Coefficient de marée'!AW9-45)/50*($D$2-$C$2)) -> 1.7420344 | AS9: =(1/2)*$Q$3*$S$3*(AR9^3)*24/1000 -> 5104.4027
V10: =$C$2+(('Coefficient de marée'!E10-45)/50*($D$2-$C$2)) -> 1.1077782 | W10: =(1/2)*$Q$3*$S$3*(V10^3)*24/1000 -> 1312.6025 | X10: =$C$2+(('Coefficient de marée'!I10-45)/50*($D$2-$C$2)) -> 0.83237751 | Y10: =(1/2)*$Q$3*$S$3*(X10^3)*24/1000 -> 556.84687 | Z10: =$C$2+(('Coefficient de marée'!M10-45)/50*($D$2-$C$2)) -> 0.81568656 | AA10: =(1/2)*$Q$3*$S$3*(Z10^3)*24/1000 -> 524.01617 | AB10: =$C$2+(('Coefficient de marée'!Q10-45)/50*($D$2-$C$2)) -> 0.77395918 | AC10: =(1/2)*$Q$3*$S$3*(AB10^3)*24/1000 -> 447.64005 | AD10: =$C$2+(('Coefficient de marée'!U10-45)/50*($D$2-$C$2)) -> 0.91583227 | AE10: =(1/2)*$Q$3*$S$3*(AD10^3)*24/1000 -> 741.69029 | AF10: =$C$2+(('Coefficient de marée'!Y10-45)/50*($D$2-$C$2)) -> 0.98259608 | AG10: =(1/2)*$Q$3*$S$3*(AF10^3)*24/1000 -> 916.00922 | AH10: =$C$2+(('Coefficient de marée'!AC10-45)/50*($D$2-$C$2)) -> 0.87410489 | AI10: =(1/2)*$Q$3*$S$3*(AH10^3)*24/1000 -> 644.85997 | AJ10: =$C$2+(('Coefficient de marée'!AG10-45)/50*($D$2-$C$2)) -> 1.0827418 | AK10: =(1/2)*$Q$3*$S$3*(AJ10^3)*24/1000 -> 1225.602 | AL10: =$C$2+(('Coefficient de marée'!AK10-45)/50*($D$2-$C$2)) -> 1.6001613 | AM10: =(1/2)*$Q$3*$S$3*(AL10^3)*24/1000 -> 3956.089 | AN10: =$C$2+(('Coefficient de marée'!AO10-45)/50*($D$2-$C$2)) -> 1.8672165 | AO10: =(1/2)*$Q$3*$S$3*(AN10^3)*24/1000 -> 6285.7747 | AP10: =$C$2+(('Coefficient de marée'!AS10-45)/50*($D$2-$C$2)) -> 1.8421801 | AQ10: =(1/2)*$Q$3*$S$3*(AP10^3)*24/1000 -> 6036.3028 | AR10: =$C$2+(('Coefficient de marée'!AW10-45)/50*($D$2-$C$2)) -> 1.6752706 | AS10: =(1/2)*$Q$3*$S$3*(AR10^3)*24/1000 -> 4539.7261
V11: =$C$2+(('Coefficient de marée'!E11-45)/50*($D$2-$C$2)) -> 1.0326689 | W11: =(1/2)*$Q$3*$S$3*(V11^3)*24/1000 -> 1063.3056 | X11: =$C$2+(('Coefficient de marée'!I11-45)/50*($D$2-$C$2)) -> 0.85741394 | Y11: =(1/2)*$Q$3*$S$3*(X11^3)*24/1000 -> 608.62023 | Z11: =$C$2+(('Coefficient de marée'!M11-45)/50*($D$2-$C$2)) -> 0.71554085 | AA11: =(1/2)*$Q$3*$S$3*(Z11^3)*24/1000 -> 353.73502 | AB11: =$C$2+(('Coefficient de marée'!Q11-45)/50*($D$2-$C$2)) -> 0.95755965 | AC11: =(1/2)*$Q$3*$S$3*(AB11^3)*24/1000 -> 847.75874 | AD11: =$C$2+(('Coefficient de marée'!U11-45)/50*($D$2-$C$2)) -> 1.0493599 | AE11: =(1/2)*$Q$3*$S$3*(AD11^3)*24/1000 -> 1115.7018 | AF11: =$C$2+(('Coefficient de marée'!Y11-45)/50*($D$2-$C$2)) -> 1.0743963 | AG11: =(1/2)*$Q$3*$S$3*(AF11^3)*24/1000 -> 1197.4801 | AH11: =$C$2+(('Coefficient de marée'!AC11-45)/50*($D$2-$C$2)) -> 0.98259608 | AI11: =(1/2)*$Q$3*$S$3*(AH11^3)*24/1000 -> 916.00922 | AJ11: =$C$2+(('Coefficient de marée'!AG11-45)/50*($D$2-$C$2)) -> 1.2830332 | AK11: =(1/2)*$Q$3*$S$3*(AJ11^3)*24/1000 -> 2039.3345 | AL11: =$C$2+(('Coefficient de marée'!AK11-45)/50*($D$2-$C$2)) -> 1.7670708 | AM11: =(1/2)*$Q$3*$S$3*(AL11^3)*24/1000 -> 5327.6615 | AN11: =$C$2+(('Coefficient de marée'!AO11-45)/50*($D$2-$C$2)) -> 1.9423258 | AO11: =(1/2)*$Q$3*$S$3*(AN11^3)*24/1000 -> 7075.2372 | AP11: =$C$2+(('Coefficient de marée'!AS11-45)/50*($D$2-$C$2)) -> 1.7086525 | AQ11: =(1/2)*$Q$3*$S$3*(AP11^3)*24/1000 -> 4816.5491 | AR11: =$C$2+(('Coefficient de marée'!AW11-45)/50*($D$2-$C$2)) -> 1.541743 | AS11: =(1/2)*$Q$3*$S$3*(AR11^3)*24/1000 -> 3538.4307
V12: =$C$2+(('Coefficient de marée'!E12-45)/50*($D$2-$C$2)) -> 1.015978 | W12: =(1/2)*$Q$3*$S$3*(V12^3)*24/1000 -> 1012.5761 | X12: =$C$2+(('Coefficient de marée'!I12-45)/50*($D$2-$C$2)) -> 0.99928703 | Y12: =(1/2)*$Q$3*$S$3*(X12^3)*24/1000 -> 963.48624 | Z12: =$C$2+(('Coefficient de marée'!M12-45)/50*($D$2-$C$2)) -> 0.7656137 | AA12: =(1/2)*$Q$3*$S$3*(Z12^3)*24/1000 -> 433.31514 | AB12: =$C$2+(('Coefficient de marée'!Q12-45)/50*($D$2-$C$2)) -> 1.1495056 | AC12: =(1/2)*$Q$3*$S$3*(AB12^3)*24/1000 -> 1466.5877 | AD12: =$C$2+(('Coefficient de marée'!U12-45)/50*($D$2-$C$2)) -> 1.174542 | AE12: =(1/2)*$Q$3*$S$3*(AD12^3)*24/1000 -> 1564.5176 | AF12: =$C$2+(('Coefficient de marée'!Y12-45)/50*($D$2-$C$2)) -> 1.1578511 | AG12: =(1/2)*$Q$3*$S$3*(AF12^3)*24/1000 -> 1498.7627 | AH12: =$C$2+(('Coefficient de marée'!AC12-45)/50*($D$2-$C$2)) -> 1.1161237 | AI12: =(1/2)*$Q$3*$S$3*(AH12^3)*24/1000 -> 1342.4921 | AJ12: =$C$2+(('Coefficient de marée'!AG12-45)/50*($D$2-$C$2)) -> 1.4582882 | AK12: =(1/2)*$Q$3*$S$3*(AJ12^3)*24/1000 -> 2994.3658 | AL12: =$C$2+(('Coefficient de marée'!AK12-45)/50*($D$2-$C$2)) -> 1.8672165 | AM12: =(1/2)*$Q$3*$S$3*(AL12^3)*24/1000 -> 6285.7747 | AN12: =$C$2+(('Coefficient de marée'!AO12-45)/50*($D$2-$C$2)) -> 1.9089439 | AO12: =(1/2)*$Q$3*$S$3*(AN12^3)*24/1000 -> 6716.6739 | AP12: =$C$2+(('Coefficient de marée'!AS12-45)/50*($D$2-$C$2)) -> 1.5000156 | AQ12: =(1/2)*$Q$3*$S$3*(AP12^3)*24/1000 -> 3258.8328 | AR12: =$C$2+(('Coefficient de marée'!AW12-45)/50*($D$2-$C$2)) -> 1.366488 | AS12: =(1/2)*$Q$3*$S$3*(AR12^3)*24/1000 -> 2463.7248
V13: =$C$2+(('Coefficient de marée'!E13-45)/50*($D$2-$C$2)) -> 1.0577054 | W13: =(1/2)*$Q$3*$S$3*(V13^3)*24/1000 -> 1142.5333 | X13: =$C$2+(('Coefficient de marée'!I13-45)/50*($D$2-$C$2)) -> 1.1995784 | Y13: =(1/2)*$Q$3*$S$3*(X13^3)*24/1000 -> 1666.7127 | Z13: =$C$2+(('Coefficient de marée'!M13-45)/50*($D$2-$C$2)) -> 0.95755965 | AA13: =(1/2)*$Q$3*$S$3*(Z13^3)*24/1000 -> 847.75874 | AB13: =$C$2+(('Coefficient de marée'!Q13-45)/50*($D$2-$C$2)) -> 1.3164151 | AC13: =(1/2)*$Q$3*$S$3*(AB13^3)*24/1000 -> 2202.6898 | AD13: =$C$2+(('Coefficient de marée'!U13-45)/50*($D$2-$C$2)) -> 1.2746877 | AE13: =(1/2)*$Q$3*$S$3*(AD13^3)*24/1000 -> 1999.7983 | AF13: =$C$2+(('Coefficient de marée'!Y13-45)/50*($D$2-$C$2)) -> 1.2246149 | AG13: =(1/2)*$Q$3*$S$3*(AF13^3)*24/1000 -> 1773.2638 | AH13: =$C$2+(('Coefficient de marée'!AC13-45)/50*($D$2-$C$2)) -> 1.2246149 | AI13: =(1/2)*$Q$3*$S$3*(AH13^3)*24/1000 -> 1773.2638 | AJ13: =$C$2+(('Coefficient de marée'!AG13-45)/50*($D$2-$C$2)) -> 1.5918158 | AK13: =(1/2)*$Q$3*$S$3*(AJ13^3)*24/1000 -> 3894.5135 | AL13: =$C$2+(('Coefficient de marée'!AK13-45)/50*($D$2-$C$2)) -> 1.8672165 | AM13: =(1/2)*$Q$3*$S$3*(AL13^3)*24/1000 -> 6285.7747 | AN13: =$C$2+(('Coefficient de marée'!AO13-45)/50*($D$2-$C$2)) -> 1.7670708 | AO13: =(1/2)*$Q$3*$S$3*(AN13^3)*24/1000 -> 5327.6615 | AP13: =$C$2+(('Coefficient de marée'!AS13-45)/50*($D$2-$C$2)) -> 1.2579968 | AQ13: =(1/2)*$Q$3*$S$3*(AP13^3)*24/1000 -> 1922.2654 | AR13: =$C$2+(('Coefficient de marée'!AW13-45)/50*($D$2-$C$2)) -> 1.1828875 | AS13: =(1/2)*$Q$3*$S$3*(AR13^3)*24/1000 -> 1598.1042
V14: =$C$2+(('Coefficient de marée'!E14-45)/50*($D$2-$C$2)) -> 1.1661965 | W14: =(1/2)*$Q$3*$S$3*(V14^3)*24/1000 -> 1531.4049 | X14: =$C$2+(('Coefficient de marée'!I14-45)/50*($D$2-$C$2)) -> 1.3831789 | Y14: =(1/2)*$Q$3*$S$3*(X14^3)*24/1000 -> 2555.1115 | Z14: =$C$2+(('Coefficient de marée'!M14-45)/50*($D$2-$C$2)) -> 1.191233 | AA14: =(1/2)*$Q$3*$S$3*(Z14^3)*24/1000 -> 1632.1681 | AB14: =$C$2+(('Coefficient de marée'!Q14-45)/50*($D$2-$C$2)) -> 1.4415972 | AC14: =(1/2)*$Q$3*$S$3*(AB14^3)*24/1000 -> 2892.7214 | AD14: =$C$2+(('Coefficient de marée'!U14-45)/50*($D$2-$C$2)) -> 1.349797 | AE14: =(1/2)*$Q$3*$S$3*(AD14^3)*24/1000 -> 2374.5436 | AF14: =$C$2+(('Coefficient de marée'!Y14-45)/50*($D$2-$C$2)) -> 1.2746877 | AG14: =(1/2)*$Q$3*$S$3*(AF14^3)*24/1000 -> 1999.7983 | AH14: =$C$2+(('Coefficient de marée'!AC14-45)/50*($D$2-$C$2)) -> 1.3247606 | AI14: =(1/2)*$Q$3*$S$3*(AH14^3)*24/1000 -> 2244.8481 | AJ14: =$C$2+(('Coefficient de marée'!AG14-45)/50*($D$2-$C$2)) -> 1.683616 | AK14: =(1/2)*$Q$3*$S$3*(AJ14^3)*24/1000 -> 4607.9095 | AL14: =$C$2+(('Coefficient de marée'!AK14-45)/50*($D$2-$C$2)) -> 1.7587253 | AM14: =(1/2)*$Q$3*$S$3*(AL14^3)*24/1000 -> 5252.5334 | AN14: =$C$2+(('Coefficient de marée'!AO14-45)/50*($D$2-$C$2)) -> 1.5333975 | AO14: =(1/2)*$Q$3*$S$3*(AN14^3)*24/1000 -> 3481.2804 | AP14: =$C$2+(('Coefficient de marée'!AS14-45)/50*($D$2-$C$2)) -> 1.0326689 | AQ14: =(1/2)*$Q$3*$S$3*(AP14^3)*24/1000 -> 1063.3056 | AR14: =$C$2+(('Coefficient de marée'!AW14-45)/50*($D$2-$C$2)) -> 1.0243235 | AS14: =(1/2)*$Q$3*$S$3*(AR14^3)*24/1000 -> 1037.7342
V15: =$C$2+(('Coefficient de marée'!E15-45)/50*($D$2-$C$2)) -> 1.3080696 | W15: =(1/2)*$Q$3*$S$3*(V15^3)*24/1000 -> 2161.0627 | X15: =$C$2+(('Coefficient de marée'!I15-45)/50*($D$2-$C$2)) -> 1.5167065 | Y15: =(1/2)*$Q$3*$S$3*(X15^3)*24/1000 -> 3368.8327 | Z15: =$C$2+(('Coefficient de marée'!M15-45)/50*($D$2-$C$2)) -> 1.3748334 | AA15: =(1/2)*$Q$3*$S$3*(Z15^3)*24/1000 -> 2509.1408 | AB15: =$C$2+(('Coefficient de marée'!Q15-45)/50*($D$2-$C$2)) -> 1.5083611 | AC15: =(1/2)*$Q$3*$S$3*(AB15^3)*24/1000 -> 3313.5284 | AD15: =$C$2+(('Coefficient de marée'!U15-45)/50*($D$2-$C$2)) -> 1.3831789 | AE15: =(1/2)*$Q$3*$S$3*(AD15^3)*24/1000 -> 2555.1115 | AF15: =$C$2+(('Coefficient de marée'!Y15-45)/50*($D$2-$C$2)) -> 1.2997242 | AG15: =(1/2)*$Q$3*$S$3*(AF15^3)*24/1000 -> 2119.9633 | AH15: =$C$2+(('Coefficient de marée'!AC15-45)/50*($D$2-$C$2)) -> 1.3998699 | AI15: =(1/2)*$Q$3*$S$3*(AH15^3)*24/1000 -> 2648.7305 | AJ15: =$C$2+(('Coefficient de marée'!AG15-45)/50*($D$2-$C$2)) -> 1.700307 | AK15: =(1/2)*$Q$3*$S$3*(AJ15^3)*24/1000 -> 4746.3176 | AL15: =$C$2+(('Coefficient de marée'!AK15-45)/50*($D$2-$C$2)) -> 1.5584339 | AM15: =(1/2)*$Q$3*$S$3*(AL15^3)*24/1000 -> 3654.6007 | AN15: =$C$2+(('Coefficient de marée'!AO15-45)/50*($D$2-$C$2)) -> 1.2413058 | AO15: =(1/2)*$Q$3*$S$3*(AN15^3)*24/1000 -> 1846.7629 | AP15: =$C$2+(('Coefficient de marée'!AS15-45)/50*($D$2-$C$2)) -> 0.88245037 | AQ15: =(1/2)*$Q$3*$S$3*(AP15^3)*24/1000 -> 663.50718 | AR15: =$C$2+(('Coefficient de marée'!AW15-45)/50*($D$2-$C$2)) -> 0.90748679 | AS15: =(1/2)*$Q$3*$S$3*(AR15^3)*24/1000 -> 721.59864
V16: =$C$2+(('Coefficient de marée'!E16-45)/50*($D$2-$C$2)) -> 1.4332518 | W16: =(1/2)*$Q$3*$S$3*(V16^3)*24/1000 -> 2842.7733 | X16: =$C$2+(('Coefficient de marée'!I16-45)/50*($D$2-$C$2)) -> 1.5918158 | Y16: =(1/2)*$Q$3*$S$3*(X16^3)*24/1000 -> 3894.5135 | Z16: =$C$2+(('Coefficient de marée'!M16-45)/50*($D$2-$C$2)) -> 1.5083611 | AA16: =(1/2)*$Q$3*$S$3*(Z16^3)*24/1000 -> 3313.5284 | AB16: =$C$2+(('Coefficient de marée'!Q16-45)/50*($D$2-$C$2)) -> 1.5333975 | AC16: =(1/2)*$Q$3*$S$3*(AB16^3)*24/1000 -> 3481.2804 | AD16: =$C$2+(('Coefficient de marée'!U16-45)/50*($D$2-$C$2)) -> 1.3915244 | AE16: =(1/2)*$Q$3*$S$3*(AD16^3)*24/1000 -> 2601.6402 | AF16: =$C$2+(('Coefficient de marée'!Y16-45)/50*($D$2-$C$2)) -> 1.2997242 | AG16: =(1/2)*$Q$3*$S$3*(AF16^3)*24/1000 -> 2119.9633 | AH16: =$C$2+(('Coefficient de marée'!AC16-45)/50*($D$2-$C$2)) -> 1.4582882 | AI16: =(1/2)*$Q$3*$S$3*(AH16^3)*24/1000 -> 2994.3658 | AJ16: =$C$2+(('Coefficient de marée'!AG16-45)/50*($D$2-$C$2)) -> 1.6418887 | AK16: =(1/2)*$Q$3*$S$3*(AJ16^3)*24/1000 -> 4273.7182 | AL16: =$C$2+(('Coefficient de marée'!AK16-45)/50*($D$2-$C$2)) -> 1.2913787 | AM16: =(1/2)*$Q$3*$S$3*(AL16^3)*24/1000 -> 2079.3884 | AN16: =$C$2+(('Coefficient de marée'!AO16-45)/50*($D$2-$C$2)) -> 0.96590512 | AO16: =(1/2)*$Q$3*$S$3*(AN16^3)*24/1000 -> 870.11805 | AP16: =$C$2+(('Coefficient de marée'!AS16-45)/50*($D$2-$C$2)) -> 0.84906846 | AQ16: =(1/2)*$Q$3*$S$3*(AP16^3)*24/1000 -> 591.02098 | AR16: =$C$2+(('Coefficient de marée'!AW16-45)/50*($D$2-$C$2)) -> 0.86575941 | AS16: =(1/2)*$Q$3*$S$3*(AR16^3)*24/1000 -> 626.56544
V17: =$C$2+(('Coefficient de marée'!E17-45)/50*($D$2-$C$2)) -> 1.5167065 | W17: =(1/2)*$Q$3*$S$3*(V17^3)*24/1000 -> 3368.8327 | X17: =$C$2+(('Coefficient de marée'!I17-45)/50*($D$2-$C$2)) -> 1.6168522 | Y17: =(1/2)*$Q$3*$S$3*(X17^3)*24/1000 -> 4081.1802 | Z17: =$C$2+(('Coefficient de marée'!M17-45)/50*($D$2-$C$2)) -> 1.5918158 | AA17: =(1/2)*$Q$3*$S$3*(Z17^3)*24/1000 -> 3894.5135 | AB17: =$C$2+(('Coefficient de marée'!Q17-45)/50*($D$2-$C$2)) -> 1.525052 | AC17: =(1/2)*$Q$3*$S$3*(AB17^3)*24/1000 -> 3424.7489 | AD17: =$C$2+(('Coefficient de marée'!U17-45)/50*($D$2-$C$2)) -> 1.366488 | AE17: =(1/2)*$Q$3*$S$3*(AD17^3)*24/1000 -> 2463.7248 | AF17: =$C$2+(('Coefficient de marée'!Y17-45)/50*($D$2-$C$2)) -> 1.2830332 | AG17: =(1/2)*$Q$3*$S$3*(AF17^3)*24/1000 -> 2039.3345 | AH17: =$C$2+(('Coefficient de marée'!AC17-45)/50*($D$2-$C$2)) -> 1.4666337 | AI17: =(1/2)*$Q$3*$S$3*(AH17^3)*24/1000 -> 3046.0689 | AJ17: =$C$2+(('Coefficient de marée'!AG17-45)/50*($D$2-$C$2)) -> 1.5083611 | AK17: =(1/2)*$Q$3*$S$3*(AJ17^3)*24/1000 -> 3313.5284 | AL17: =$C$2+(('Coefficient de marée'!AK17-45)/50*($D$2-$C$2)) -> 1.0076325 | AM17: =(1/2)*$Q$3*$S$3*(AL17^3)*24/1000 -> 987.82786 | AN17: =$C$2+(('Coefficient de marée'!AO17-45)/50*($D$2-$C$2)) -> 0.79899561 | AO17: =(1/2)*$Q$3*$S$3*(AN17^3)*24/1000 -> 492.50194 | AP17: =$C$2+(('Coefficient de marée'!AS17-45)/50*($D$2-$C$2)) -> 0.89079584 | AQ17: =(1/2)*$Q$3*$S$3*(AP17^3)*24/1000 -> 682.51046 | AR17: =$C$2+(('Coefficient de marée'!AW17-45)/50*($D$2-$C$2)) -> 0.85741394 | AS17: =(1/2)*$Q$3*$S$3*(AR17^3)*24/1000 -> 608.62023
V18: =$C$2+(('Coefficient de marée'!E18-45)/50*($D$2-$C$2)) -> 1.5500884 | W18: =(1/2)*$Q$3*$S$3*(V18^3)*24/1000 -> 3596.203 | X18: =$C$2+(('Coefficient de marée'!I18-45)/50*($D$2-$C$2)) -> 1.5834703 | Y18: =(1/2)*$Q$3*$S$3*(X18^3)*24/1000 -> 3833.5803 | Z18: =$C$2+(('Coefficient de marée'!M18-45)/50*($D$2-$C$2)) -> 1.6168522 | AA18: =(1/2)*$Q$3*$S$3*(Z18^3)*24/1000 -> 4081.1802 | AB18: =$C$2+(('Coefficient de marée'!Q18-45)/50*($D$2-$C$2)) -> 1.4666337 | AC18: =(1/2)*$Q$3*$S$3*(AB18^3)*24/1000 -> 3046.0689 | AD18: =$C$2+(('Coefficient de marée'!U18-45)/50*($D$2-$C$2)) -> 1.3080696 | AE18: =(1/2)*$Q$3*$S$3*(AD18^3)*24/1000 -> 2161.0627 | AF18: =$C$2+(('Coefficient de marée'!Y18-45)/50*($D$2-$C$2)) -> 1.2413058 | AG18: =(1/2)*$Q$3*$S$3*(AF18^3)*24/1000 -> 1846.7629 | AH18: =$C$2+(('Coefficient de marée'!AC18-45)/50*($D$2-$C$2)) -> 1.4332518 | AI18: =(1/2)*$Q$3*$S$3*(AH18^3)*24/1000 -> 2842.7733 | AJ18: =$C$2+(('Coefficient de marée'!AG18-45)/50*($D$2-$C$2)) -> 1.3080696 | AK18: =(1/2)*$Q$3*$S$3*(AJ18^3)*24/1000 -> 2161.0627 | AL18: =$C$2+(('Coefficient de marée'!AK18-45)/50*($D$2-$C$2)) -> 0.83237751 | AM18: =(1/2)*$Q$3*$S$3*(AL18^3)*24/1000 -> 556.84687 | AN18: =$C$2+(('Coefficient de marée'!AO18-45)/50*($D$2-$C$2)) -> 0.77395918 | AO18: =(1/2)*$Q$3*$S$3*(AN18^3)*24/1000 -> 447.64005 | AP18: =$C$2+(('Coefficient de marée'!AS18-45)/50*($D$2-$C$2)) -> 0.99928703 | AQ18: =(1/2)*$Q$3*$S$3*(AP18^3)*24/1000 -> 963.48624 | AR18: =$C$2+(('Coefficient de marée'!AW18-45)/50*($D$2-$C$2)) -> 0.91583227 | AS18: =(1/2)*$Q$3*$S$3*(AR18^3)*24/1000 -> 741.69029
